Workbook

Sheet Auswertung
A1: TOTO WM 2026 — Auswertung Gruppenphase
A3: Rang | B3: Name | C3: Spieltipps | D3: Tortipps | E3: Sechzehntel- finalisten | F3: Total
A4: =IF(B4="","",RANK(F4,$F$4:$F$43)) -> 15 | B4: Sebi | C4: =IF(B4="","",INDIRECT("'"&B4&"'!B154")) -> 190 | D4: =IF(B4="","",INDIRECT("'"&B4&"'!B155")) -> 205 | E4: =IF(B4="","",INDIRECT("'"&B4&"'!B156")) -> 135 | F4: =IF(B4="","",INDIRECT("'"&B4&"'!B157")) -> 530
A5: =IF(B5="","",RANK(F5,$F$4:$F$43)) -> 9 | B5: Nick | C5: =IF(B5="","",INDIRECT("'"&B5&"'!B154")) -> 220 | D5: =IF(B5="","",INDIRECT("'"&B5&"'!B155")) -> 202 | E5: =IF(B5="","",INDIRECT("'"&B5&"'!B156")) -> 135 | F5: =IF(B5="","",INDIRECT("'"&B5&"'!B157")) -> 557
A6: =IF(B6="","",RANK(F6,$F$4:$F$43)) -> 14 | B6: Nici | C6: =IF(B6="","",INDIRECT("'"&B6&"'!B154")) -> 190 | D6: =IF(B6="","",INDIRECT("'"&B6&"'!B155")) -> 216 | E6: =IF(B6="","",INDIRECT("'"&B6&"'!B156")) -> 125 | F6: =IF(B6="","",INDIRECT("'"&B6&"'!B157")) -> 531
A7: =IF(B7="","",RANK(F7,$F$4:$F$43)) -> 13 | B7: Mads | C7: =IF(B7="","",INDIRECT("'"&B7&"'!B154")) -> 215 | D7: =IF(B7="","",INDIRECT("'"&B7&"'!B155")) -> 188 | E7: =IF(B7="","",INDIRECT("'"&B7&"'!B156")) -> 135 | F7: =IF(B7="","",INDIRECT("'"&B7&"'!B157")) -> 538
A8: =IF(B8="","",RANK(F8,$F$4:$F$43)) -> 2 | B8: Julius | C8: =IF(B8="","",INDIRECT("'"&B8&"'!B154")) -> 225 | D8: =IF(B8="","",INDIRECT("'"&B8&"'!B155")) -> 221 | E8: =IF(B8="","",INDIRECT("'"&B8&"'!B156")) -> 135 | F8: =IF(B8="","",INDIRECT("'"&B8&"'!B157")) -> 581
A9: =IF(B9="","",RANK(F9,$F$4:$F$43)) -> 3 | B9: Dennis | C9: =IF(B9="","",INDIRECT("'"&B9&"'!B154")) -> 215 | D9: =IF(B9="","",INDIRECT("'"&B9&"'!B155")) -> 233 | E9: =IF(B9="","",INDIRECT("'"&B9&"'!B156")) -> 130 | F9: =IF(B9="","",INDIRECT("'"&B9&"'!B157")) -> 578
A10: =IF(B10="","",RANK(F10,$F$4:$F$43)) -> 6 | B10: Heidi | C10: =IF(B10="","",INDIRECT("'"&B10&"'!B154")) -> 215 | D10: =IF(B10="","",INDIRECT("'"&B10&"'!B155")) -> 218 | E10: =IF(B10="","",INDIRECT("'"&B10&"'!B156")) -> 130 | F10: =IF(B10="","",INDIRECT("'"&B10&"'!B157")) -> 563
A11: =IF(B11="","",RANK(F11,$F$4:$F$43)) -> 12 | B11: Mirco | C11: =IF(B11="","",INDIRECT("'"&B11&"'!B154")) -> 195 | D11: =IF(B11="","",INDIRECT("'"&B11&"'!B155")) -> 213 | E11: =IF(B11="","",INDIRECT("'"&B11&"'!B156")) -> 140 | F11: =IF(B11="","",INDIRECT("'"&B11&"'!B157")) -> 548
A12: =IF(B12="","",RANK(F12,$F$4:$F$43)) -> 17 | B12: Tobe | C12: =IF(B12="","",INDIRECT("'"&B12&"'!B154")) -> 170 | D12: =IF(B12="","",INDIRECT("'"&B12&"'!B155")) -> 198 | E12: =IF(B12="","",INDIRECT("'"&B12&"'!B156")) -> 125 | F12: =IF(B12="","",INDIRECT("'"&B12&"'!B157")) -> 493
A13: =IF(B13="","",RANK(F13,$F$4:$F$43)) -> 4 | B13: Urs | C13: =IF(B13="","",INDIRECT("'"&B13&"'!B154")) -> 225 | D13: =IF(B13="","",INDIRECT("'"&B13&"'!B155")) -> 221 | E13: =IF(B13="","",INDIRECT("'"&B13&"'!B156")) -> 130 | F13: =IF(B13="","",INDIRECT("'"&B13&"'!B157")) -> 576
A14: =IF(B14="","",RANK(F14,$F$4:$F$43)) -> 7 | B14: Max | C14: =IF(B14="","",INDIRECT("'"&B14&"'!B154")) -> 215 | D14: =IF(B14="","",INDIRECT("'"&B14&"'!B155")) -> 222 | E14: =IF(B14="","",INDIRECT("'"&B14&"'!B156")) -> 125 | F14: =IF(B14="","",INDIRECT("'"&B14&"'!B157")) -> 562
A15: =IF(B15="","",RANK(F15,$F$4:$F$43)) -> 11 | B15: Vito+Jonas | C15: =IF(B15="","",INDIRECT("'"&B15&"'!B154")) -> 210 | D15: =IF(B15="","",INDIRECT("'"&B15&"'!B155")) -> 209 | E15: =IF(B15="","",INDIRECT("'"&B15&"'!B156")) -> 135 | F15: =IF(B15="","",INDIRECT("'"&B15&"'!B157")) -> 554
... A20: =IF(B20="","",RANK(F20,$F$4:$F$43)) -> 4 | B20: Claude (out of competition) | C20: =IF(B20="","",INDIRECT("'"&B20&"'!B154")) -> 220 | D20: =IF(B20="","",INDIRECT("'"&B20&"'!B155")) -> 226 | E20: =IF(B20="","",INDIRECT("'"&B20&"'!B156")) -> 130 | F20: =IF(B20="","",INDIRECT("'"&B20&"'!B157")) -> 576
A21: =IF(B21="","",RANK(F21,$F$4:$F$43)) | C21: =IF(B21="","",INDIRECT("'"&B21&"'!B154")) | D21: =IF(B21="","",INDIRECT("'"&B21&"'!B155")) | E21: =IF(B21="","",INDIRECT("'"&B21&"'!B156")) | F21: =IF(B21="","",INDIRECT("'"&B21&"'!B157"))
A22: =IF(B22="","",RANK(F22,$F$4:$F$43)) | C22: =IF(B22="","",INDIRECT("'"&B22&"'!B154")) | D22: =IF(B22="","",INDIRECT("'"&B22&"'!B155")) | E22: =IF(B22="","",INDIRECT("'"&B22&"'!B156")) | F22: =IF(B22="","",INDIRECT("'"&B22&"'!B157"))
A23: =IF(B23="","",RANK(F23,$F$4:$F$43)) | C23: =IF(B23="","",INDIRECT("'"&B23&"'!B154")) | D23: =IF(B23="","",INDIRECT("'"&B23&"'!B155")) | E23: =IF(B23="","",INDIRECT("'"&B23&"'!B156")) | F23: =IF(B23="","",INDIRECT("'"&B23&"'!B157"))
A24: =IF(B24="","",RANK(F24,$F$4:$F$43)) | C24: =IF(B24="","",INDIRECT("'"&B24&"'!B154")) | D24: =IF(B24="","",INDIRECT("'"&B24&"'!B155")) | E24: =IF(B24="","",INDIRECT("'"&B24&"'!B156")) | F24: =IF(B24="","",INDIRECT("'"&B24&"'!B157"))
A25: =IF(B25="","",RANK(F25,$F$4:$F$43)) | C25: =IF(B25="","",INDIRECT("'"&B25&"'!B154")) | D25: =IF(B25="","",INDIRECT("'"&B25&"'!B155")) | E25: =IF(B25="","",INDIRECT("'"&B25&"'!B156")) | F25: =IF(B25="","",INDIRECT("'"&B25&"'!B157"))
A26: =IF(B26="","",RANK(F26,$F$4:$F$43)) | C26: =IF(B26="","",INDIRECT("'"&B26&"'!B154")) | D26: =IF(B26="","",INDIRECT("'"&B26&"'!B155")) | E26: =IF(B26="","",INDIRECT("'"&B26&"'!B156")) | F26: =IF(B26="","",INDIRECT("'"&B26&"'!B157"))
A27: =IF(B27="","",RANK(F27,$F$4:$F$43)) | C27: =IF(B27="","",INDIRECT("'"&B27&"'!B154")) | D27: =IF(B27="","",INDIRECT("'"&B27&"'!B155")) | E27: =IF(B27="","",INDIRECT("'"&B27&"'!B156")) | F27: =IF(B27="","",INDIRECT("'"&B27&"'!B157"))
A28: =IF(B28="","",RANK(F28,$F$4:$F$43)) | C28: =IF(B28="","",INDIRECT("'"&B28&"'!B154")) | D28: =IF(B28="","",INDIRECT("'"&B28&"'!B155")) | E28: =IF(B28="","",INDIRECT("'"&B28&"'!B156")) | F28: =IF(B28="","",INDIRECT("'"&B28&"'!B157"))
A29: =IF(B29="","",RANK(F29,$F$4:$F$43)) | C29: =IF(B29="","",INDIRECT("'"&B29&"'!B154")) | D29: =IF(B29="","",INDIRECT("'"&B29&"'!B155")) | E29: =IF(B29="","",INDIRECT("'"&B29&"'!B156")) | F29: =IF(B29="","",INDIRECT("'"&B29&"'!B157"))
A30: =IF(B30="","",RANK(F30,$F$4:$F$43)) | C30: =IF(B30="","",INDIRECT("'"&B30&"'!B154")) | D30: =IF(B30="","",INDIRECT("'"&B30&"'!B155")) | E30: =IF(B30="","",INDIRECT("'"&B30&"'!B156")) | F30: =IF(B30="","",INDIRECT("'"&B30&"'!B157"))
A31: =IF(B31="","",RANK(F31,$F$4:$F$43)) | C31: =IF(B31="","",INDIRECT("'"&B31&"'!B154")) | D31: =IF(B31="","",INDIRECT("'"&B31&"'!B155")) | E31: =IF(B31="","",INDIRECT("'"&B31&"'!B156")) | F31: =IF(B31="","",INDIRECT("'"&B31&"'!B157"))
A32: =IF(B32="","",RANK(F32,$F$4:$F$43)) | C32: =IF(B32="","",INDIRECT("'"&B32&"'!B154")) | D32: =IF(B32="","",INDIRECT("'"&B32&"'!B155")) | E32: =IF(B32="","",INDIRECT("'"&B32&"'!B156")) | F32: =IF(B32="","",INDIRECT("'"&B32&"'!B157"))
... A43: =IF(B43="","",RANK(F43,$F$4:$F$43)) | C43: =IF(B43="","",INDIRECT("'"&B43&"'!B154")) | D43: =IF(B43="","",INDIRECT("'"&B43&"'!B155")) | E43: =IF(B43="","",INDIRECT("'"&B43&"'!B156")) | F43: =IF(B43="","",INDIRECT("'"&B43&"'!B157"))
A46: Spieler hinzufügen:
A47: 1. Rechtsklick auf ein bestehendes Spieler-Blatt → "Blatt verschieben oder kopieren" → "Kopie erstellen"
A48: 2. Neues Blatt umbenennen (Rechtsklick → "Umbenennen") zum Namen des Spielers
A49: 3. Hier auf der Auswertung den Namen in die nächste freie Zeile in Spalte B eintragen
A51: Spieler entfernen:
A52: 1. Spieler-Blatt löschen (Rechtsklick → "Löschen")
A53: 2. Namen aus Spalte B entfernen

Sheet Realität
B1: Gruppe A | H1: Gruppe B | O1: Gruppe C | V1: Gruppe D | AC1: Gruppe E | AJ1: Gruppe F
B3: Runde 1 | I3: Runde 1 | P3: Runde 1 | W3: Runde 1 | AD3: Runde 1 | AK3: Runde 1
B4: Mexiko | C4: Südafrika | I4: Kanada | J4: Bosnien-Herz. | P4: Brasilien | Q4: Marokko | W4: USA | X4: Paraguay | AD4: Deutschland | AE4: Curacao | AK4: Niederlande | AL4: Japan
B5: 2 | C5: 0 | I5: 1 | J5: 1 | P5: 1 | Q5: 1 | W5: 4 | X5: 1 | AD5: 7 | AE5: 1 | AK5: 2 | AL5: 2
B6: =IF(B5=C5,"Unentschieden",IF(B5>C5,B4,C4)) -> Mexiko | I6: =IF(I5=J5,"Unentschieden",IF(I5>J5,I4,J4)) -> Unentschieden | P6: =IF(P5=Q5,"Unentschieden",IF(P5>Q5,P4,Q4)) -> Unentschieden | W6: =IF(W5=X5,"Unentschieden",IF(W5>X5,W4,X4)) -> USA | AD6: =IF(AD5=AE5,"Unentschieden",IF(AD5>AE5,AD4,AE4)) -> Deutschland | AK6: =IF(AK5=AL5,"Unentschieden",IF(AK5>AL5,AK4,AL4)) -> Unentschieden
B7: =IF(B5=C5,1,IF(B5>C5,3,0)) -> 3 | C7: =IF(C5=B5,1,IF(C5>B5,3,0)) -> 0 | I7: =IF(I5=J5,1,IF(I5>J5,3,0)) -> 1 | J7: =IF(J5=I5,1,IF(J5>I5,3,0)) -> 1 | P7: =IF(P5=Q5,1,IF(P5>Q5,3,0)) -> 1 | Q7: =IF(Q5=P5,1,IF(Q5>P5,3,0)) -> 1 | W7: =IF(W5=X5,1,IF(W5>X5,3,0)) -> 3 | X7: =IF(X5=W5,1,IF(X5>W5,3,0)) -> 0 | AD7: =IF(AD5=AE5,1,IF(AD5>AE5,3,0)) -> 3 | AE7: =IF(AE5=AD5,1,IF(AE5>AD5,3,0)) -> 0 | AK7: =IF(AK5=AL5,1,IF(AK5>AL5,3,0)) -> 1 | AL7: =IF(AL5=AK5,1,IF(AL5>AK5,3,0)) -> 1
B9: Südkorea | C9: Tschechien | I9: Katar | J9: Schweiz | P9: Haiti | Q9: Schottland | W9: Australien | X9: Türkei | AD9: Elfenbeinküste | AE9: Ecuador | AK9: Schweden | AL9: Tunesien
B10: 2 | C10: 1 | I10: 1 | J10: 1 | P10: 0 | Q10: 1 | W10: 2 | X10: 0 | AD10: 1 | AE10: 0 | AK10: 5 | AL10: 1
B11: =IF(B10=C10,"Unentschieden",IF(B10>C10,B9,C9)) -> Südkorea | I11: =IF(I10=J10,"Unentschieden",IF(I10>J10,I9,J9)) -> Unentschieden | P11: =IF(P10=Q10,"Unentschieden",IF(P10>Q10,P9,Q9)) -> Schottland | W11: =IF(W10=X10,"Unentschieden",IF(W10>X10,W9,X9)) -> Australien | AD11: =IF(AD10=AE10,"Unentschieden",IF(AD10>AE10,AD9,AE9)) -> Elfenbeinküste | AK11: =IF(AK10=AL10,"Unentschieden",IF(AK10>AL10,AK9,AL9)) -> Schweden
B12: =IF(B10=C10,1,IF(B10>C10,3,0)) -> 3 | C12: =IF(C10=B10,1,IF(C10>B10,3,0)) -> 0 | I12: =IF(I10=J10,1,IF(I10>J10,3,0)) -> 1 | J12: =IF(J10=I10,1,IF(J10>I10,3,0)) -> 1 | P12: =IF(P10=Q10,1,IF(P10>Q10,3,0)) -> 0 | Q12: =IF(Q10=P10,1,IF(Q10>P10,3,0)) -> 3 | W12: =IF(W10=X10,1,IF(W10>X10,3,0)) -> 3 | X12: =IF(X10=W10,1,IF(X10>W10,3,0)) -> 0 | AD12: =IF(AD10=AE10,1,IF(AD10>AE10,3,0)) -> 3 | AE12: =IF(AE10=AD10,1,IF(AE10>AD10,3,0)) -> 0 | AK12: =IF(AK10=AL10,1,IF(AK10>AL10,3,0)) -> 3 | AL12: =IF(AL10=AK10,1,IF(AL10>AK10,3,0)) -> 0
B14: Runde 2 | I14: Runde 2 | P14: Runde 2 | W14: Runde 2 | AD14: Runde 2 | AK14: Runde 2
B15: Tschechien | C15: Südafrika | I15: Schweiz | J15: Bosnien-Herz. | P15: Schottland | Q15: Marokko | W15: Türkei | X15: Paraguay | AD15: Ecuador | AE15: Curacao | AK15: Tunesien | AL15: Japan
B16: 1 | C16: 1 | I16: 4 | J16: 1 | P16: 0 | Q16: 1 | W16: 0 | X16: 1 | AD16: 0 | AE16: 0 | AK16: 0 | AL16: 4
B17: =IF(B16=C16,"Unentschieden",IF(B16>C16,B15,C15)) -> Unentschieden | I17: =IF(I16=J16,"Unentschieden",IF(I16>J16,I15,J15)) -> Schweiz | P17: =IF(P16=Q16,"Unentschieden",IF(P16>Q16,P15,Q15)) -> Marokko | W17: =IF(W16=X16,"Unentschieden",IF(W16>X16,W15,X15)) -> Paraguay | AD17: =IF(AD16=AE16,"Unentschieden",IF(AD16>AE16,AD15,AE15)) -> Unentschieden | AK17: =IF(AK16=AL16,"Unentschieden",IF(AK16>AL16,AK15,AL15)) -> Japan
B18: =IF(B16=C16,1,IF(B16>C16,3,0)) -> 1 | C18: =IF(C16=B16,1,IF(C16>B16,3,0)) -> 1 | I18: =IF(I16=J16,1,IF(I16>J16,3,0)) -> 3 | J18: =IF(J16=I16,1,IF(J16>I16,3,0)) -> 0 | P18: =IF(P16=Q16,1,IF(P16>Q16,3,0)) -> 0 | Q18: =IF(Q16=P16,1,IF(Q16>P16,3,0)) -> 3 | W18: =IF(W16=X16,1,IF(W16>X16,3,0)) -> 0 | X18: =IF(X16=W16,1,IF(X16>W16,3,0)) -> 3 | AD18: =IF(AD16=AE16,1,IF(AD16>AE16,3,0)) -> 1 | AE18: =IF(AE16=AD16,1,IF(AE16>AD16,3,0)) -> 1 | AK18: =IF(AK16=AL16,1,IF(AK16>AL16,3,0)) -> 0 | AL18: =IF(AL16=AK16,1,IF(AL16>AK16,3,0)) -> 3
B20: Mexiko | C20: Südkorea | I20: Kanada | J20: Katar | P20: Brasilien | Q20: Haiti | W20: USA | X20: Australien | AD20: Deutschland | AE20: Elfenbeinküste | AK20: Niederlande | AL20: Schweden
B21: 1 | C21: 0 | I21: 6 | J21: 0 | P21: 3 | Q21: 0 | W21: 2 | X21: 0 | AD21: 2 | AE21: 1 | AK21: 5 | AL21: 1
B22: =IF(B21=C21,"Unentschieden",IF(B21>C21,B20,C20)) -> Mexiko | I22: =IF(I21=J21,"Unentschieden",IF(I21>J21,I20,J20)) -> Kanada | P22: =IF(P21=Q21,"Unentschieden",IF(P21>Q21,P20,Q20)) -> Brasilien | W22: =IF(W21=X21,"Unentschieden",IF(W21>X21,W20,X20)) -> USA | AD22: =IF(AD21=AE21,"Unentschieden",IF(AD21>AE21,AD20,AE20)) -> Deutschland | AK22: =IF(AK21=AL21,"Unentschieden",IF(AK21>AL21,AK20,AL20)) -> Niederlande
B23: =IF(B21=C21,1,IF(B21>C21,3,0)) -> 3 | C23: =IF(C21=B21,1,IF(C21>B21,3,0)) -> 0 | I23: =IF(I21=J21,1,IF(I21>J21,3,0)) -> 3 | J23: =IF(J21=I21,1,IF(J21>I21,3,0)) -> 0 | P23: =IF(P21=Q21,1,IF(P21>Q21,3,0)) -> 3 | Q23: =IF(Q21=P21,1,IF(Q21>P21,3,0)) -> 0 | W23: =IF(W21=X21,1,IF(W21>X21,3,0)) -> 3 | X23: =IF(X21=W21,1,IF(X21>W21,3,0)) -> 0 | AD23: =IF(AD21=AE21,1,IF(AD21>AE21,3,0)) -> 3 | AE23: =IF(AE21=AD21,1,IF(AE21>AD21,3,0)) -> 0 | AK23: =IF(AK21=AL21,1,IF(AK21>AL21,3,0)) -> 3 | AL23: =IF(AL21=AK21,1,IF(AL21>AK21,3,0)) -> 0
B25: Runde 3 | I25: Runde 3 | P25: Runde 3 | W25: Runde 3 | AD25: Runde 3 | AK25: Runde 3
B26: Südafrika | C26: Südkorea | I26: Bosnien-Herz. | J26: Katar | P26: Marokko | Q26: Haiti | W26: Paraguay | X26: Australien | AD26: Curacao | AE26: Elfenbeinküste | AK26: Japan | AL26: Schweden
B27: 1 | C27: 0 | I27: 3 | J27: 1 | P27: 4 | Q27: 2 | W27: 0 | X27: 0 | AD27: 0 | AE27: 2 | AK27: 1 | AL27: 1
B28: =IF(B27=C27,"Unentschieden",IF(B27>C27,B26,C26)) -> Südafrika | I28: =IF(I27=J27,"Unentschieden",IF(I27>J27,I26,J26)) -> Bosnien-Herz. | P28: =IF(P27=Q27,"Unentschieden",IF(P27>Q27,P26,Q26)) -> Marokko | W28: =IF(W27=X27,"Unentschieden",IF(W27>X27,W26,X26)) -> Unentschieden | AD28: =IF(AD27=AE27,"Unentschieden",IF(AD27>AE27,AD26,AE26)) -> Elfenbeinküste | AK28: =IF(AK27=AL27,"Unentschieden",IF(AK27>AL27,AK26,AL26)) -> Unentschieden
B29: =IF(B27=C27,1,IF(B27>C27,3,0)) -> 3 | C29: =IF(C27=B27,1,IF(C27>B27,3,0)) -> 0 | I29: =IF(I27=J27,1,IF(I27>J27,3,0)) -> 3 | J29: =IF(J27=I27,1,IF(J27>I27,3,0)) -> 0 | P29: =IF(P27=Q27,1,IF(P27>Q27,3,0)) -> 3 | Q29: =IF(Q27=P27,1,IF(Q27>P27,3,0)) -> 0 | W29: =IF(W27=X27,1,IF(W27>X27,3,0)) -> 1 | X29: =IF(X27=W27,1,IF(X27>W27,3,0)) -> 1 | AD29: =IF(AD27=AE27,1,IF(AD27>AE27,3,0)) -> 0 | AE29: =IF(AE27=AD27,1,IF(AE27>AD27,3,0)) -> 3 | AK29: =IF(AK27=AL27,1,IF(AK27>AL27,3,0)) -> 1 | AL29: =IF(AL27=AK27,1,IF(AL27>AK27,3,0)) -> 1
B31: Tschechien | C31: Mexiko | I31: Schweiz | J31: Kanada | P31: Schottland | Q31: Brasilien | W31: Türkei | X31: USA | AD31: Ecuador | AE31: Deutschland | AK31: Tunesien | AL31: Niederlande
B32: 0 | C32: 3 | I32: 2 | J32: 1 | P32: 0 | Q32: 3 | W32: 3 | X32: 2 | AD32: 2 | AE32: 1 | AK32: 1 | AL32: 3
B33: =IF(B32=C32,"Unentschieden",IF(B32>C32,B31,C31)) -> Mexiko | I33: =IF(I32=J32,"Unentschieden",IF(I32>J32,I31,J31)) -> Schweiz | P33: =IF(P32=Q32,"Unentschieden",IF(P32>Q32,P31,Q31)) -> Brasilien | W33: =IF(W32=X32,"Unentschieden",IF(W32>X32,W31,X31)) -> Türkei | AD33: =IF(AD32=AE32,"Unentschieden",IF(AD32>AE32,AD31,AE31)) -> Ecuador | AK33: =IF(AK32=AL32,"Unentschieden",IF(AK32>AL32,AK31,AL31)) -> Niederlande
B34: =IF(B32=C32,1,IF(B32>C32,3,0)) -> 0 | C34: =IF(C32=B32,1,IF(C32>B32,3,0)) -> 3 | I34: =IF(I32=J32,1,IF(I32>J32,3,0)) -> 3 | J34: =IF(J32=I32,1,IF(J32>I32,3,0)) -> 0 | P34: =IF(P32=Q32,1,IF(P32>Q32,3,0)) -> 0 | Q34: =IF(Q32=P32,1,IF(Q32>P32,3,0)) -> 3 | W34: =IF(W32=X32,1,IF(W32>X32,3,0)) -> 3 | X34: =IF(X32=W32,1,IF(X32>W32,3,0)) -> 0 | AD34: =IF(AD32=AE32,1,IF(AD32>AE32,3,0)) -> 3 | AE34: =IF(AE32=AD32,1,IF(AE32>AD32,3,0)) -> 0 | AK34: =IF(AK32=AL32,1,IF(AK32>AL32,3,0)) -> 0 | AL34: =IF(AL32=AK32,1,IF(AL32>AK32,3,0)) -> 3
B36: Land | C36: Punkte | D36: T | E36: GT | F36: TD | I36: Land | J36: Punkte | K36: T | L36: GT | M36: TD | P36: Land | Q36: Punkte | R36: T | S36: GT | T36: TD | W36: Land | X36: Punkte | Y36: T | Z36: GT | AA36: TD | AD36: Land | AE36: Punkte | AF36: T | AG36: GT | AH36: TD | AK36: Land | AL36: Punkte | AM36: T | AN36: GT | AO36: TD
B37: Mexiko | C37: =B7+B23+C34 -> 9 | D37: =B5+B21+C32 -> 6 | E37: =C5+C21+B32 -> 0 | F37: =D37-E37 -> 6 | I37: Kanada | J37: =I7+I23+J34 -> 4 | K37: =I5+I21+J32 -> 8 | L37: =J5+J21+I32 -> 3 | M37: =K37-L37 -> 5 | P37: Brasilien | Q37: =P7+P23+Q34 -> 7 | R37: =P5+P21+Q32 -> 7 | S37: =Q5+Q21+P32 -> 1 | T37: =R37-S37 -> 6 | W37: USA | X37: =W7+W23+X34 -> 6 | Y37: =W5+W21+X32 -> 8 | Z37: =X5+X21+W32 -> 4 | AA37: =Y37-Z37 -> 4 | AD37: Deutschland | AE37: =AD7+AD23+AE34 -> 6 | AF37: =AD5+AD21+AE32 -> 10 | AG37: =AE5+AE21+AD32 -> 4 | AH37: =AF37-AG37 -> 6 | AK37: Niederlande | AL37: =AK7+AK23+AL34 -> 7 | AM37: =AK5+AK21+AL32 -> 10 | AN37: =AL5+AL21+AK32 -> 4 | AO37: =AM37-AN37 -> 6
B38: Südafrika | C38: =C7+C18+B29 -> 4 | D38: =C5+C16+B27 -> 2 | E38: =B5+B16+C27 -> 3 | F38: =D38-E38 -> -1 | I38: Bosnien-Herz. | J38: =J7+J18+I29 -> 4 | K38: =J5+J16+I27 -> 5 | L38: =I5+I16+J27 -> 6 | M38: =K38-L38 -> -1 | P38: Marokko | Q38: =Q7+Q18+P29 -> 7 | R38: =Q5+Q16+P27 -> 6 | S38: =P5+P16+Q27 -> 3 | T38: =R38-S38 -> 3 | W38: Paraguay | X38: =X7+X18+W29 -> 4 | Y38: =X5+X16+W27 -> 2 | Z38: =W5+W16+X27 -> 4 | AA38: =Y38-Z38 -> -2 | AD38: Curacao | AE38: =AE7+AE18+AD29 -> 1 | AF38: =AE5+AE16+AD27 -> 1 | AG38: =AD5+AD16+AE27 -> 9 | AH38: =AF38-AG38 -> -8 | AK38: Japan | AL38: =AL7+AL18+AK29 -> 5 | AM38: =AL5+AL16+AK27 -> 7 | AN38: =AK5+AK16+AL27 -> 3 | AO38: =AM38-AN38 -> 4
B39: Südkorea | C39: =B12+C23+C29 -> 3 | D39: =B10+C21+C27 -> 2 | E39: =C10+B21+B27 -> 3 | F39: =D39-E39 -> -1 | I39: Katar | J39: =I12+J23+J29 -> 1 | K39: =I10+J21+J27 -> 2 | L39: =J10+I21+I27 -> 10 | M39: =K39-L39 -> -8 | P39: Haiti | Q39: =P12+Q23+Q29 -> 0 | R39: =P10+Q21+Q27 -> 2 | S39: =Q10+P21+P27 -> 8 | T39: =R39-S39 -> -6 | W39: Australien | X39: =W12+X23+X29 -> 4 | Y39: =W10+X21+X27 -> 2 | Z39: =X10+W21+W27 -> 2 | AA39: =Y39-Z39 -> 0 | AD39: Elfenbeinküste | AE39: =AD12+AE23+AE29 -> 6 | AF39: =AD10+AE21+AE27 -> 4 | AG39: =AE10+AD21+AD27 -> 2 | AH39: =AF39-AG39 -> 2 | AK39: Schweden | AL39: =AK12+AL23+AL29 -> 4 | AM39: =AK10+AL21+AL27 -> 7 | AN39: =AL10+AK21+AK27 -> 7 | AO39: =AM39-AN39 -> 0
B40: Tschechien | C40: =C12+B18+B34 -> 1 | D40: =C10+B16+B32 -> 2 | E40: =B10+C16+C32 -> 6 | F40: =D40-E40 -> -4 | I40: Schweiz | J40: =J12+I18+I34 -> 7 | K40: =J10+I16+I32 -> 7 | L40: =I10+J16+J32 -> 3 | M40: =K40-L40 -> 4 | P40: Schottland | Q40: =Q12+P18+P34 -> 3 | R40: =Q10+P16+P32 -> 1 | S40: =P10+Q16+Q32 -> 4 | T40: =R40-S40 -> -3 | W40: Türkei | X40: =X12+W18+W34 -> 3 | Y40: =X10+W16+W32 -> 3 | Z40: =W10+X16+X32 -> 5 | AA40: =Y40-Z40 -> -2 | AD40: Ecuador | AE40: =AE12+AD18+AD34 -> 4 | AF40: =AE10+AD16+AD32 -> 2 | AG40: =AD10+AE16+AE32 -> 2 | AH40: =AF40-AG40 -> 0 | AK40: Tunesien | AL40: =AL12+AK18+AK34 -> 0 | AM40: =AL10+AK16+AK32 -> 2 | AN40: =AK10+AL16+AL32 -> 12 | AO40: =AM40-AN40 -> -10
B42: Rangliste: | I42: Rangliste: | P42: Rangliste: | W42: Rangliste: | AD42: Rangliste: | AK42: Rangliste:
A43: 1 | B43: {=_xlfn.SORTBY(B37:B40,C37:C40,-1,F37:F40,-1,D37:D40,-1)} -> Mexiko | C43: {=_xlfn.SORTBY(C37:C40,C37:C40,-1,F37:F40,-1,D37:D40,-1)} -> 9 | D43: {=_xlfn.SORTBY(D37:D40,C37:C40,-1,F37:F40,-1,D37:D40,-1)} -> 6 | E43: {=_xlfn.SORTBY(E37:E40,C37:C40,-1,F37:F40,-1,D37:D40,-1)} -> 0 | F43: {=_xlfn.SORTBY(F37:F40,C37:C40,-1,F37:F40,-1,D37:D40,-1)} -> 6 | H43: 1 | I43: {=_xlfn.SORTBY(I37:I40,J37:J40,-1,M37:M40,-1,K37:K40,-1)} -> Schweiz | J43: {=_xlfn.SORTBY(J37:J40,J37:J40,-1,M37:M40,-1,K37:K40,-1)} -> 7 | K43: {=_xlfn.SORTBY(K37:K40,J37:J40,-1,M37:M40,-1,K37:K40,-1)} -> 7 | L43: {=_xlfn.SORTBY(L37:L40,J37:J40,-1,M37:M40,-1,K37:K40,-1)} -> 3 | M43: {=_xlfn.SORTBY(M37:M40,J37:J40,-1,M37:M40,-1,K37:K40,-1)} -> 4 | O43: 1 | P43: {=_xlfn.SORTBY(P37:P40,Q37:Q40,-1,T37:T40,-1,R37:R40,-1)} -> Brasilien | Q43: {=_xlfn.SORTBY(Q37:Q40,Q37:Q40,-1,T37:T40,-1,R37:R40,-1)} -> 7 | R43: {=_xlfn.SORTBY(R37:R40,Q37:Q40,-1,T37:T40,-1,R37:R40,-1)} -> 7 | S43: {=_xlfn.SORTBY(S37:S40,Q37:Q40,-1,T37:T40,-1,R37:R40,-1)} -> 1 | T43: {=_xlfn.SORTBY(T37:T40,Q37:Q40,-1,T37:T40,-1,R37:R40,-1)} -> 6 | V43: 1 | W43: {=_xlfn.SORTBY(W37:W40,X37:X40,-1,AA37:AA40,-1,Y37:Y40,-1)} -> USA | X43: {=_xlfn.SORTBY(X37:X40,X37:X40,-1,AA37:AA40,-1,Y37:Y40,-1)} -> 6 | Y43: {=_xlfn.SORTBY(Y37:Y40,X37:X40,-1,AA37:AA40,-1,Y37:Y40,-1)} -> 8 | Z43: {=_xlfn.SORTBY(Z37:Z40,X37:X40,-1,AA37:AA40,-1,Y37:Y40,-1)} -> 4 | AA43: {=_xlfn.SORTBY(AA37:AA40,X37:X40,-1,AA37:AA40,-1,Y37:Y40,-1)} -> 4 | AC43: 1 | AD43: {=_xlfn.SORTBY(AD37:AD40,AE37:AE40,-1,AH37:AH40,-1,AF37:AF40,-1)} -> Deutschland | AE43: {=_xlfn.SORTBY(AE37:AE40,AE37:AE40,-1,AH37:AH40,-1,AF37:AF40,-1)} -> 6 | AF43: {=_xlfn.SORTBY(AF37:AF40,AE37:AE40,-1,AH37:AH40,-1,AF37:AF40,-1)} -> 10 | AG43: {=_xlfn.SORTBY(AG37:AG40,AE37:AE40,-1,AH37:AH40,-1,AF37:AF40,-1)} -> 4 | AH43: {=_xlfn.SORTBY(AH37:AH40,AE37:AE40,-1,AH37:AH40,-1,AF37:AF40,-1)} -> 6 | AJ43: 1 | AK43: {=_xlfn.SORTBY(AK37:AK40,AL37:AL40,-1,AO37:AO40,-1,AM37:AM40,-1)} -> Niederlande | AL43: {=_xlfn.SORTBY(AL37:AL40,AL37:AL40,-1,AO37:AO40,-1,AM37:AM40,-1)} -> 7 | AM43: {=_xlfn.SORTBY(AM37:AM40,AL37:AL40,-1,AO37:AO40,-1,AM37:AM40,-1)} -> 10 | AN43: {=_xlfn.SORTBY(AN37:AN40,AL37:AL40,-1,AO37:AO40,-1,AM37:AM40,-1)} -> 4 | AO43: {=_xlfn.SORTBY(AO37:AO40,AL37:AL40,-1,AO37:AO40,-1,AM37:AM40,-1)} -> 6
A44: 2 | B44: Südafrika | C44: 4 | D44: 2 | E44: 3 | F44: -1 | H44: 2 | I44: Kanada | J44: 4 | K44: 8 | L44: 3 | M44: 5 | O44: 2 | P44: Marokko | Q44: 7 | R44: 6 | S44: 3 | T44: 3 | V44: 2 | W44: Australien | X44: 4 | Y44: 2 | Z44: 2 | AA44: 0 | AC44: 2 | AD44: Elfenbeinküste | AE44: 6 | AF44: 4 | AG44: 2 | AH44: 2 | AJ44: 2 | AK44: Japan | AL44: 5 | AM44: 7 | AN44: 3 | AO44: 4
A45: 3 | B45: Südkorea | C45: 3 | D45: 2 | E45: 3 | F45: -1 | H45: 3 | I45: Bosnien-Herz. | J45: 4 | K45: 5 | L45: 6 | M45: -1 | O45: 3 | P45: Schottland | Q45: 3 | R45: 1 | S45: 4 | T45: -3 | V45: 3 | W45: Paraguay | X45: 4 | Y45: 2 | Z45: 4 | AA45: -2 | AC45: 3 | AD45: Ecuador | AE45: 4 | AF45: 2 | AG45: 2 | AH45: 0 | AJ45: 3 | AK45: Schweden | AL45: 4 | AM45: 7 | AN45: 7 | AO45: 0
A46: 4 | B46: Tschechien | C46: 1 | D46: 2 | E46: 6 | F46: -4 | H46: 4 | I46: Katar | J46: 1 | K46: 2 | L46: 10 | M46: -8 | O46: 4 | P46: Haiti | Q46: 0 | R46: 2 | S46: 8 | T46: -6 | V46: 4 | W46: Türkei | X46: 3 | Y46: 3 | Z46: 5 | AA46: -2 | AC46: 4 | AD46: Curacao | AE46: 1 | AF46: 1 | AG46: 9 | AH46: -8 | AJ46: 4 | AK46: Tunesien | AL46: 0 | AM46: 2 | AN46: 12 | AO46: -10
A48: Gruppe G | H48: Gruppe H | O48: Gruppe I | V48: Gruppe J | AC48: Gruppe K | AJ48: Gruppe L
B50: Runde 1 | I50: Runde 1 | P50: Runde 1 | W50: Runde 1 | AD50: Runde 1 | AK50: Runde 1
...

Sheet Sebi
B1: Gruppe A | H1: Gruppe B | O1: Gruppe C | V1: Gruppe D | AC1: Gruppe E | AJ1: Gruppe F
B3: Runde 1 | I3: Runde 1 | P3: Runde 1 | W3: Runde 1 | AD3: Runde 1 | AK3: Runde 1
B4: Mexiko | C4: Südafrika | I4: Kanada | J4: Bosnien-Herz. | P4: Brasilien | Q4: Marokko | W4: USA | X4: Paraguay | AD4: Deutschland | AE4: Curacao | AK4: Niederlande | AL4: Japan
B5: 4 | C5: 0 | I5: 1 | J5: 2 | P5: 2 | Q5: 1 | W5: 2 | X5: 1 | AD5: 4 | AE5: 1 | AK5: 2 | AL5: 0
B6: =IF(B5=C5,"Unentschieden",IF(B5>C5,B4,C4)) -> Mexiko | I6: =IF(I5=J5,"Unentschieden",IF(I5>J5,I4,J4)) -> Bosnien-Herz. | P6: =IF(P5=Q5,"Unentschieden",IF(P5>Q5,P4,Q4)) -> Brasilien | W6: =IF(W5=X5,"Unentschieden",IF(W5>X5,W4,X4)) -> USA | AD6: =IF(AD5=AE5,"Unentschieden",IF(AD5>AE5,AD4,AE4)) -> Deutschland | AK6: =IF(AK5=AL5,"Unentschieden",IF(AK5>AL5,AK4,AL4)) -> Niederlande
B7: =IF(B5=C5,1,IF(B5>C5,3,0)) -> 3 | C7: =IF(C5=B5,1,IF(C5>B5,3,0)) -> 0 | I7: =IF(I5=J5,1,IF(I5>J5,3,0)) -> 0 | J7: =IF(J5=I5,1,IF(J5>I5,3,0)) -> 3 | P7: =IF(P5=Q5,1,IF(P5>Q5,3,0)) -> 3 | Q7: =IF(Q5=P5,1,IF(Q5>P5,3,0)) -> 0 | W7: =IF(W5=X5,1,IF(W5>X5,3,0)) -> 3 | X7: =IF(X5=W5,1,IF(X5>W5,3,0)) -> 0 | AD7: =IF(AD5=AE5,1,IF(AD5>AE5,3,0)) -> 3 | AE7: =IF(AE5=AD5,1,IF(AE5>AD5,3,0)) -> 0 | AK7: =IF(AK5=AL5,1,IF(AK5>AL5,3,0)) -> 3 | AL7: =IF(AL5=AK5,1,IF(AL5>AK5,3,0)) -> 0
B9: Südkorea | C9: Tschechien | I9: Katar | J9: Schweiz | P9: Haiti | Q9: Schottland | W9: Australien | X9: Türkei | AD9: Elfenbeinküste | AE9: Ecuador | AK9: Schweden | AL9: Tunesien
B10: 0 | C10: 1 | I10: 0 | J10: 3 | P10: 0 | Q10: 2 | W10: 0 | X10: 1 | AD10: 1 | AE10: 1 | AK10: 2 | AL10: 0
B11: =IF(B10=C10,"Unentschieden",IF(B10>C10,B9,C9)) -> Tschechien | I11: =IF(I10=J10,"Unentschieden",IF(I10>J10,I9,J9)) -> Schweiz | P11: =IF(P10=Q10,"Unentschieden",IF(P10>Q10,P9,Q9)) -> Schottland | W11: =IF(W10=X10,"Unentschieden",IF(W10>X10,W9,X9)) -> Türkei | AD11: =IF(AD10=AE10,"Unentschieden",IF(AD10>AE10,AD9,AE9)) -> Unentschieden | AK11: =IF(AK10=AL10,"Unentschieden",IF(AK10>AL10,AK9,AL9)) -> Schweden
B12: =IF(B10=C10,1,IF(B10>C10,3,0)) -> 0 | C12: =IF(C10=B10,1,IF(C10>B10,3,0)) -> 3 | I12: =IF(I10=J10,1,IF(I10>J10,3,0)) -> 0 | J12: =IF(J10=I10,1,IF(J10>I10,3,0)) -> 3 | P12: =IF(P10=Q10,1,IF(P10>Q10,3,0)) -> 0 | Q12: =IF(Q10=P10,1,IF(Q10>P10,3,0)) -> 3 | W12: =IF(W10=X10,1,IF(W10>X10,3,0)) -> 0 | X12: =IF(X10=W10,1,IF(X10>W10,3,0)) -> 3 | AD12: =IF(AD10=AE10,1,IF(AD10>AE10,3,0)) -> 1 | AE12: =IF(AE10=AD10,1,IF(AE10>AD10,3,0)) -> 1 | AK12: =IF(AK10=AL10,1,IF(AK10>AL10,3,0)) -> 3 | AL12: =IF(AL10=AK10,1,IF(AL10>AK10,3,0)) -> 0
B14: Runde 2 | I14: Runde 2 | P14: Runde 2 | W14: Runde 2 | AD14: Runde 2 | AK14: Runde 2
B15: Tschechien | C15: Südafrika | I15: Schweiz | J15: Bosnien-Herz. | P15: Schottland | Q15: Marokko | W15: Türkei | X15: Paraguay | AD15: Ecuador | AE15: Curacao | AK15: Tunesien | AL15: Japan
B16: 2 | C16: 0 | I16: 2 | J16: 1 | P16: 1 | Q16: 0 | W16: 1 | X16: 1 | AD16: 2 | AE16: 0 | AK16: 0 | AL16: 1
B17: =IF(B16=C16,"Unentschieden",IF(B16>C16,B15,C15)) -> Tschechien | I17: =IF(I16=J16,"Unentschieden",IF(I16>J16,I15,J15)) -> Schweiz | P17: =IF(P16=Q16,"Unentschieden",IF(P16>Q16,P15,Q15)) -> Schottland | W17: =IF(W16=X16,"Unentschieden",IF(W16>X16,W15,X15)) -> Unentschieden | AD17: =IF(AD16=AE16,"Unentschieden",IF(AD16>AE16,AD15,AE15)) -> Ecuador | AK17: =IF(AK16=AL16,"Unentschieden",IF(AK16>AL16,AK15,AL15)) -> Japan
B18: =IF(B16=C16,1,IF(B16>C16,3,0)) -> 3 | C18: =IF(C16=B16,1,IF(C16>B16,3,0)) -> 0 | I18: =IF(I16=J16,1,IF(I16>J16,3,0)) -> 3 | J18: =IF(J16=I16,1,IF(J16>I16,3,0)) -> 0 | P18: =IF(P16=Q16,1,IF(P16>Q16,3,0)) -> 3 | Q18: =IF(Q16=P16,1,IF(Q16>P16,3,0)) -> 0 | W18: =IF(W16=X16,1,IF(W16>X16,3,0)) -> 1 | X18: =IF(X16=W16,1,IF(X16>W16,3,0)) -> 1 | AD18: =IF(AD16=AE16,1,IF(AD16>AE16,3,0)) -> 3 | AE18: =IF(AE16=AD16,1,IF(AE16>AD16,3,0)) -> 0 | AK18: =IF(AK16=AL16,1,IF(AK16>AL16,3,0)) -> 0 | AL18: =IF(AL16=AK16,1,IF(AL16>AK16,3,0)) -> 3
B20: Mexiko | C20: Südkorea | I20: Kanada | J20: Katar | P20: Brasilien | Q20: Haiti | W20: USA | X20: Australien | AD20: Deutschland | AE20: Elfenbeinküste | AK20: Niederlande | AL20: Schweden
B21: 2 | C21: 1 | I21: 2 | J21: 1 | P21: 5 | Q21: 0 | W21: 1 | X21: 1 | AD21: 1 | AE21: 1 | AK21: 2 | AL21: 1
B22: =IF(B21=C21,"Unentschieden",IF(B21>C21,B20,C20)) -> Mexiko | I22: =IF(I21=J21,"Unentschieden",IF(I21>J21,I20,J20)) -> Kanada | P22: =IF(P21=Q21,"Unentschieden",IF(P21>Q21,P20,Q20)) -> Brasilien | W22: =IF(W21=X21,"Unentschieden",IF(W21>X21,W20,X20)) -> Unentschieden | AD22: =IF(AD21=AE21,"Unentschieden",IF(AD21>AE21,AD20,AE20)) -> Unentschieden | AK22: =IF(AK21=AL21,"Unentschieden",IF(AK21>AL21,AK20,AL20)) -> Niederlande
B23: =IF(B21=C21,1,IF(B21>C21,3,0)) -> 3 | C23: =IF(C21=B21,1,IF(C21>B21,3,0)) -> 0 | I23: =IF(I21=J21,1,IF(I21>J21,3,0)) -> 3 | J23: =IF(J21=I21,1,IF(J21>I21,3,0)) -> 0 | P23: =IF(P21=Q21,1,IF(P21>Q21,3,0)) -> 3 | Q23: =IF(Q21=P21,1,IF(Q21>P21,3,0)) -> 0 | W23: =IF(W21=X21,1,IF(W21>X21,3,0)) -> 1 | X23: =IF(X21=W21,1,IF(X21>W21,3,0)) -> 1 | AD23: =IF(AD21=AE21,1,IF(AD21>AE21,3,0)) -> 1 | AE23: =IF(AE21=AD21,1,IF(AE21>AD21,3,0)) -> 1 | AK23: =IF(AK21=AL21,1,IF(AK21>AL21,3,0)) -> 3 | AL23: =IF(AL21=AK21,1,IF(AL21>AK21,3,0)) -> 0
B25: Runde 3 | I25: Runde 3 | P25: Runde 3 | W25: Runde 3 | AD25: Runde 3 | AK25: Runde 3
B26: Südafrika | C26: Südkorea | I26: Bosnien-Herz. | J26: Katar | P26: Marokko | Q26: Haiti | W26: Paraguay | X26: Australien | AD26: Curacao | AE26: Elfenbeinküste | AK26: Japan | AL26: Schweden
B27: 0 | C27: 2 | I27: 2 | J27: 0 | P27: 4 | Q27: 0 | W27: 1 | X27: 2 | AD27: 1 | AE27: 1 | AK27: 2 | AL27: 2
B28: =IF(B27=C27,"Unentschieden",IF(B27>C27,B26,C26)) -> Südkorea | I28: =IF(I27=J27,"Unentschieden",IF(I27>J27,I26,J26)) -> Bosnien-Herz. | P28: =IF(P27=Q27,"Unentschieden",IF(P27>Q27,P26,Q26)) -> Marokko | W28: =IF(W27=X27,"Unentschieden",IF(W27>X27,W26,X26)) -> Australien | AD28: =IF(AD27=AE27,"Unentschieden",IF(AD27>AE27,AD26,AE26)) -> Unentschieden | AK28: =IF(AK27=AL27,"Unentschieden",IF(AK27>AL27,AK26,AL26)) -> Unentschieden
B29: =IF(B27=C27,1,IF(B27>C27,3,0)) -> 0 | C29: =IF(C27=B27,1,IF(C27>B27,3,0)) -> 3 | I29: =IF(I27=J27,1,IF(I27>J27,3,0)) -> 3 | J29: =IF(J27=I27,1,IF(J27>I27,3,0)) -> 0 | P29: =IF(P27=Q27,1,IF(P27>Q27,3,0)) -> 3 | Q29: =IF(Q27=P27,1,IF(Q27>P27,3,0)) -> 0 | W29: =IF(W27=X27,1,IF(W27>X27,3,0)) -> 0 | X29: =IF(X27=W27,1,IF(X27>W27,3,0)) -> 3 | AD29: =IF(AD27=AE27,1,IF(AD27>AE27,3,0)) -> 1 | AE29: =IF(AE27=AD27,1,IF(AE27>AD27,3,0)) -> 1 | AK29: =IF(AK27=AL27,1,IF(AK27>AL27,3,0)) -> 1 | AL29: =IF(AL27=AK27,1,IF(AL27>AK27,3,0)) -> 1
B31: Tschechien | C31: Mexiko | I31: Schweiz | J31: Kanada | P31: Schottland | Q31: Brasilien | W31: Türkei | X31: USA | AD31: Ecuador | AE31: Deutschland | AK31: Tunesien | AL31: Niederlande
B32: 1 | C32: 1 | I32: 1 | J32: 0 | P32: 0 | Q32: 1 | W32: 2 | X32: 1 | AD32: 1 | AE32: 3 | AK32: 0 | AL32: 4
B33: =IF(B32=C32,"Unentschieden",IF(B32>C32,B31,C31)) -> Unentschieden | I33: =IF(I32=J32,"Unentschieden",IF(I32>J32,I31,J31)) -> Schweiz | P33: =IF(P32=Q32,"Unentschieden",IF(P32>Q32,P31,Q31)) -> Brasilien | W33: =IF(W32=X32,"Unentschieden",IF(W32>X32,W31,X31)) -> Türkei | AD33: =IF(AD32=AE32,"Unentschieden",IF(AD32>AE32,AD31,AE31)) -> Deutschland | AK33: =IF(AK32=AL32,"Unentschieden",IF(AK32>AL32,AK31,AL31)) -> Niederlande
B34: =IF(B32=C32,1,IF(B32>C32,3,0)) -> 1 | C34: =IF(C32=B32,1,IF(C32>B32,3,0)) -> 1 | I34: =IF(I32=J32,1,IF(I32>J32,3,0)) -> 3 | J34: =IF(J32=I32,1,IF(J32>I32,3,0)) -> 0 | P34: =IF(P32=Q32,1,IF(P32>Q32,3,0)) -> 0 | Q34: =IF(Q32=P32,1,IF(Q32>P32,3,0)) -> 3 | W34: =IF(W32=X32,1,IF(W32>X32,3,0)) -> 3 | X34: =IF(X32=W32,1,IF(X32>W32,3,0)) -> 0 | AD34: =IF(AD32=AE32,1,IF(AD32>AE32,3,0)) -> 0 | AE34: =IF(AE32=AD32,1,IF(AE32>AD32,3,0)) -> 3 | AK34: =IF(AK32=AL32,1,IF(AK32>AL32,3,0)) -> 0 | AL34: =IF(AL32=AK32,1,IF(AL32>AK32,3,0)) -> 3
B36: Land | C36: Punkte | D36: T | E36: GT | F36: TD | I36: Land | J36: Punkte | K36: T | L36: GT | M36: TD | P36: Land | Q36: Punkte | R36: T | S36: GT | T36: TD | W36: Land | X36: Punkte | Y36: T | Z36: GT | AA36: TD | AD36: Land | AE36: Punkte | AF36: T | AG36: GT | AH36: TD | AK36: Land | AL36: Punkte | AM36: T | AN36: GT | AO36: TD
B37: Mexiko | C37: =B7+B23+C34 -> 7 | D37: =B5+B21+C32 -> 7 | E37: =C5+C21+B32 -> 2 | F37: =D37-E37 -> 5 | I37: Kanada | J37: =I7+I23+J34 -> 3 | K37: =I5+I21+J32 -> 3 | L37: =J5+J21+I32 -> 4 | M37: =K37-L37 -> -1 | P37: Brasilien | Q37: =P7+P23+Q34 -> 9 | R37: =P5+P21+Q32 -> 8 | S37: =Q5+Q21+P32 -> 1 | T37: =R37-S37 -> 7 | W37: USA | X37: =W7+W23+X34 -> 4 | Y37: =W5+W21+X32 -> 4 | Z37: =X5+X21+W32 -> 4 | AA37: =Y37-Z37 -> 0 | AD37: Deutschland | AE37: =AD7+AD23+AE34 -> 7 | AF37: =AD5+AD21+AE32 -> 8 | AG37: =AE5+AE21+AD32 -> 3 | AH37: =AF37-AG37 -> 5 | AK37: Niederlande | AL37: =AK7+AK23+AL34 -> 9 | AM37: =AK5+AK21+AL32 -> 8 | AN37: =AL5+AL21+AK32 -> 1 | AO37: =AM37-AN37 -> 7
B38: Südafrika | C38: =C7+C18+B29 -> 0 | D38: =C5+C16+B27 -> 0 | E38: =B5+B16+C27 -> 8 | F38: =D38-E38 -> -8 | I38: Bosnien-Herz. | J38: =J7+J18+I29 -> 6 | K38: =J5+J16+I27 -> 5 | L38: =I5+I16+J27 -> 3 | M38: =K38-L38 -> 2 | P38: Marokko | Q38: =Q7+Q18+P29 -> 3 | R38: =Q5+Q16+P27 -> 5 | S38: =P5+P16+Q27 -> 3 | T38: =R38-S38 -> 2 | W38: Paraguay | X38: =X7+X18+W29 -> 1 | Y38: =X5+X16+W27 -> 3 | Z38: =W5+W16+X27 -> 5 | AA38: =Y38-Z38 -> -2 | AD38: Curacao | AE38: =AE7+AE18+AD29 -> 1 | AF38: =AE5+AE16+AD27 -> 2 | AG38: =AD5+AD16+AE27 -> 7 | AH38: =AF38-AG38 -> -5 | AK38: Japan | AL38: =AL7+AL18+AK29 -> 4 | AM38: =AL5+AL16+AK27 -> 3 | AN38: =AK5+AK16+AL27 -> 4 | AO38: =AM38-AN38 -> -1
B39: Südkorea | C39: =B12+C23+C29 -> 3 | D39: =B10+C21+C27 -> 3 | E39: =C10+B21+B27 -> 3 | F39: =D39-E39 -> 0 | I39: Katar | J39: =I12+J23+J29 -> 0 | K39: =I10+J21+J27 -> 1 | L39: =J10+I21+I27 -> 7 | M39: =K39-L39 -> -6 | P39: Haiti | Q39: =P12+Q23+Q29 -> 0 | R39: =P10+Q21+Q27 -> 0 | S39: =Q10+P21+P27 -> 11 | T39: =R39-S39 -> -11 | W39: Australien | X39: =W12+X23+X29 -> 4 | Y39: =W10+X21+X27 -> 3 | Z39: =X10+W21+W27 -> 3 | AA39: =Y39-Z39 -> 0 | AD39: Elfenbeinküste | AE39: =AD12+AE23+AE29 -> 3 | AF39: =AD10+AE21+AE27 -> 3 | AG39: =AE10+AD21+AD27 -> 3 | AH39: =AF39-AG39 -> 0 | AK39: Schweden | AL39: =AK12+AL23+AL29 -> 4 | AM39: =AK10+AL21+AL27 -> 5 | AN39: =AL10+AK21+AK27 -> 4 | AO39: =AM39-AN39 -> 1
B40: Tschechien | C40: =C12+B18+B34 -> 7 | D40: =C10+B16+B32 -> 4 | E40: =B10+C16+C32 -> 1 | F40: =D40-E40 -> 3 | I40: Schweiz | J40: =J12+I18+I34 -> 9 | K40: =J10+I16+I32 -> 6 | L40: =I10+J16+J32 -> 1 | M40: =K40-L40 -> 5 | P40: Schottland | Q40: =Q12+P18+P34 -> 6 | R40: =Q10+P16+P32 -> 3 | S40: =P10+Q16+Q32 -> 1 | T40: =R40-S40 -> 2 | W40: Türkei | X40: =X12+W18+W34 -> 7 | Y40: =X10+W16+W32 -> 4 | Z40: =W10+X16+X32 -> 2 | AA40: =Y40-Z40 -> 2 | AD40: Ecuador | AE40: =AE12+AD18+AD34 -> 4 | AF40: =AE10+AD16+AD32 -> 4 | AG40: =AD10+AE16+AE32 -> 4 | AH40: =AF40-AG40 -> 0 | AK40: Tunesien | AL40: =AL12+AK18+AK34 -> 0 | AM40: =AL10+AK16+AK32 -> 0 | AN40: =AK10+AL16+AL32 -> 7 | AO40: =AM40-AN40 -> -7
B42: Rangliste: | I42: Rangliste: | P42: Rangliste: | W42: Rangliste: | AD42: Rangliste: | AK42: Rangliste:
A43: 1 | B43: {=_xlfn.SORTBY(B37:B40,C37:C40,-1,F37:F40,-1,D37:D40,-1)} -> Mexiko | C43: {=_xlfn.SORTBY(C37:C40,C37:C40,-1,F37:F40,-1,D37:D40,-1)} -> 7 | D43: {=_xlfn.SORTBY(D37:D40,C37:C40,-1,F37:F40,-1,D37:D40,-1)} -> 7 | E43: {=_xlfn.SORTBY(E37:E40,C37:C40,-1,F37:F40,-1,D37:D40,-1)} -> 2 | F43: {=_xlfn.SORTBY(F37:F40,C37:C40,-1,F37:F40,-1,D37:D40,-1)} -> 5 | H43: 1 | I43: {=_xlfn.SORTBY(I37:I40,J37:J40,-1,M37:M40,-1,K37:K40,-1)} -> Schweiz | J43: {=_xlfn.SORTBY(J37:J40,J37:J40,-1,M37:M40,-1,K37:K40,-1)} -> 9 | K43: {=_xlfn.SORTBY(K37:K40,J37:J40,-1,M37:M40,-1,K37:K40,-1)} -> 6 | L43: {=_xlfn.SORTBY(L37:L40,J37:J40,-1,M37:M40,-1,K37:K40,-1)} -> 1 | M43: {=_xlfn.SORTBY(M37:M40,J37:J40,-1,M37:M40,-1,K37:K40,-1)} -> 5 | O43: 1 | P43: {=_xlfn.SORTBY(P37:P40,Q37:Q40,-1,T37:T40,-1,R37:R40,-1)} -> Brasilien | Q43: {=_xlfn.SORTBY(Q37:Q40,Q37:Q40,-1,T37:T40,-1,R37:R40,-1)} -> 9 | R43: {=_xlfn.SORTBY(R37:R40,Q37:Q40,-1,T37:T40,-1,R37:R40,-1)} -> 8 | S43: {=_xlfn.SORTBY(S37:S40,Q37:Q40,-1,T37:T40,-1,R37:R40,-1)} -> 1 | T43: {=_xlfn.SORTBY(T37:T40,Q37:Q40,-1,T37:T40,-1,R37:R40,-1)} -> 7 | V43: 1 | W43: {=_xlfn.SORTBY(W37:W40,X37:X40,-1,AA37:AA40,-1,Y37:Y40,-1)} -> Türkei | X43: {=_xlfn.SORTBY(X37:X40,X37:X40,-1,AA37:AA40,-1,Y37:Y40,-1)} -> 7 | Y43: {=_xlfn.SORTBY(Y37:Y40,X37:X40,-1,AA37:AA40,-1,Y37:Y40,-1)} -> 4 | Z43: {=_xlfn.SORTBY(Z37:Z40,X37:X40,-1,AA37:AA40,-1,Y37:Y40,-1)} -> 2 | AA43: {=_xlfn.SORTBY(AA37:AA40,X37:X40,-1,AA37:AA40,-1,Y37:Y40,-1)} -> 2 | AC43: 1 | AD43: {=_xlfn.SORTBY(AD37:AD40,AE37:AE40,-1,AH37:AH40,-1,AF37:AF40,-1)} -> Deutschland | AE43: {=_xlfn.SORTBY(AE37:AE40,AE37:AE40,-1,AH37:AH40,-1,AF37:AF40,-1)} -> 7 | AF43: {=_xlfn.SORTBY(AF37:AF40,AE37:AE40,-1,AH37:AH40,-1,AF37:AF40,-1)} -> 8 | AG43: {=_xlfn.SORTBY(AG37:AG40,AE37:AE40,-1,AH37:AH40,-1,AF37:AF40,-1)} -> 3 | AH43: {=_xlfn.SORTBY(AH37:AH40,AE37:AE40,-1,AH37:AH40,-1,AF37:AF40,-1)} -> 5 | AJ43: 1 | AK43: {=_xlfn.SORTBY(AK37:AK40,AL37:AL40,-1,AO37:AO40,-1,AM37:AM40,-1)} -> Niederlande | AL43: {=_xlfn.SORTBY(AL37:AL40,AL37:AL40,-1,AO37:AO40,-1,AM37:AM40,-1)} -> 9 | AM43: {=_xlfn.SORTBY(AM37:AM40,AL37:AL40,-1,AO37:AO40,-1,AM37:AM40,-1)} -> 8 | AN43: {=_xlfn.SORTBY(AN37:AN40,AL37:AL40,-1,AO37:AO40,-1,AM37:AM40,-1)} -> 1 | AO43: {=_xlfn.SORTBY(AO37:AO40,AL37:AL40,-1,AO37:AO40,-1,AM37:AM40,-1)} -> 7
A44: 2 | B44: Tschechien | C44: 7 | D44: 4 | E44: 1 | F44: 3 | H44: 2 | I44: Bosnien-Herz. | J44: 6 | K44: 5 | L44: 3 | M44: 2 | O44: 2 | P44: Schottland | Q44: 6 | R44: 3 | S44: 1 | T44: 2 | V44: 2 | W44: USA | X44: 4 | Y44: 4 | Z44: 4 | AA44: 0 | AC44: 2 | AD44: Ecuador | AE44: 4 | AF44: 4 | AG44: 4 | AH44: 0 | AJ44: 2 | AK44: Schweden | AL44: 4 | AM44: 5 | AN44: 4 | AO44: 1
A45: 3 | B45: Südkorea | C45: 3 | D45: 3 | E45: 3 | F45: 0 | H45: 3 | I45: Kanada | J45: 3 | K45: 3 | L45: 4 | M45: -1 | O45: 3 | P45: Marokko | Q45: 3 | R45: 5 | S45: 3 | T45: 2 | V45: 3 | W45: Australien | X45: 4 | Y45: 3 | Z45: 3 | AA45: 0 | AC45: 3 | AD45: Elfenbeinküste | AE45: 3 | AF45: 3 | AG45: 3 | AH45: 0 | AJ45: 3 | AK45: Japan | AL45: 4 | AM45: 3 | AN45: 4 | AO45: -1
A46: 4 | B46: Südafrika | C46: 0 | D46: 0 | E46: 8 | F46: -8 | H46: 4 | I46: Katar | J46: 0 | K46: 1 | L46: 7 | M46: -6 | O46: 4 | P46: Haiti | Q46: 0 | R46: 0 | S46: 11 | T46: -11 | V46: 4 | W46: Paraguay | X46: 1 | Y46: 3 | Z46: 5 | AA46: -2 | AC46: 4 | AD46: Curacao | AE46: 1 | AF46: 2 | AG46: 7 | AH46: -5 | AJ46: 4 | AK46: Tunesien | AL46: 0 | AM46: 0 | AN46: 7 | AO46: -7
A48: Gruppe G | H48: Gruppe H | O48: Gruppe I | V48: Gruppe J | AC48: Gruppe K | AJ48: Gruppe L
B50: Runde 1 | I50: Runde 1 | P50: Runde 1 | W50: Runde 1 | AD50: Runde 1 | AK50: Runde 1
...

Sheet Nick
B1: Gruppe A | H1: Gruppe B | O1: Gruppe C | V1: Gruppe D | AC1: Gruppe E | AJ1: Gruppe F
B3: Runde 1 | I3: Runde 1 | P3: Runde 1 | W3: Runde 1 | AD3: Runde 1 | AK3: Runde 1
B4: Mexiko | C4: Südafrika | I4: Kanada | J4: Bosnien-Herz. | P4: Brasilien | Q4: Marokko | W4: USA | X4: Paraguay | AD4: Deutschland | AE4: Curacao | AK4: Niederlande | AL4: Japan
B5: 2 | C5: 0 | I5: 1 | J5: 3 | P5: 2 | Q5: 0 | W5: 0 | X5: 2 | AD5: 4 | AE5: 0 | AK5: 1 | AL5: 2
B6: =IF(B5=C5,"Unentschieden",IF(B5>C5,B4,C4)) -> Mexiko | I6: =IF(I5=J5,"Unentschieden",IF(I5>J5,I4,J4)) -> Bosnien-Herz. | P6: =IF(P5=Q5,"Unentschieden",IF(P5>Q5,P4,Q4)) -> Brasilien | W6: =IF(W5=X5,"Unentschieden",IF(W5>X5,W4,X4)) -> Paraguay | AD6: =IF(AD5=AE5,"Unentschieden",IF(AD5>AE5,AD4,AE4)) -> Deutschland | AK6: =IF(AK5=AL5,"Unentschieden",IF(AK5>AL5,AK4,AL4)) -> Japan
B7: =IF(B5=C5,1,IF(B5>C5,3,0)) -> 3 | C7: =IF(C5=B5,1,IF(C5>B5,3,0)) -> 0 | I7: =IF(I5=J5,1,IF(I5>J5,3,0)) -> 0 | J7: =IF(J5=I5,1,IF(J5>I5,3,0)) -> 3 | P7: =IF(P5=Q5,1,IF(P5>Q5,3,0)) -> 3 | Q7: =IF(Q5=P5,1,IF(Q5>P5,3,0)) -> 0 | W7: =IF(W5=X5,1,IF(W5>X5,3,0)) -> 0 | X7: =IF(X5=W5,1,IF(X5>W5,3,0)) -> 3 | AD7: =IF(AD5=AE5,1,IF(AD5>AE5,3,0)) -> 3 | AE7: =IF(AE5=AD5,1,IF(AE5>AD5,3,0)) -> 0 | AK7: =IF(AK5=AL5,1,IF(AK5>AL5,3,0)) -> 0 | AL7: =IF(AL5=AK5,1,IF(AL5>AK5,3,0)) -> 3
B9: Südkorea | C9: Tschechien | I9: Katar | J9: Schweiz | P9: Haiti | Q9: Schottland | W9: Australien | X9: Türkei | AD9: Elfenbeinküste | AE9: Ecuador | AK9: Schweden | AL9: Tunesien
B10: 2 | C10: 1 | I10: 0 | J10: 3 | P10: 0 | Q10: 1 | W10: 1 | X10: 3 | AD10: 3 | AE10: 2 | AK10: 0 | AL10: 2
B11: =IF(B10=C10,"Unentschieden",IF(B10>C10,B9,C9)) -> Südkorea | I11: =IF(I10=J10,"Unentschieden",IF(I10>J10,I9,J9)) -> Schweiz | P11: =IF(P10=Q10,"Unentschieden",IF(P10>Q10,P9,Q9)) -> Schottland | W11: =IF(W10=X10,"Unentschieden",IF(W10>X10,W9,X9)) -> Türkei | AD11: =IF(AD10=AE10,"Unentschieden",IF(AD10>AE10,AD9,AE9)) -> Elfenbeinküste | AK11: =IF(AK10=AL10,"Unentschieden",IF(AK10>AL10,AK9,AL9)) -> Tunesien
B12: =IF(B10=C10,1,IF(B10>C10,3,0)) -> 3 | C12: =IF(C10=B10,1,IF(C10>B10,3,0)) -> 0 | I12: =IF(I10=J10,1,IF(I10>J10,3,0)) -> 0 | J12: =IF(J10=I10,1,IF(J10>I10,3,0)) -> 3 | P12: =IF(P10=Q10,1,IF(P10>Q10,3,0)) -> 0 | Q12: =IF(Q10=P10,1,IF(Q10>P10,3,0)) -> 3 | W12: =IF(W10=X10,1,IF(W10>X10,3,0)) -> 0 | X12: =IF(X10=W10,1,IF(X10>W10,3,0)) -> 3 | AD12: =IF(AD10=AE10,1,IF(AD10>AE10,3,0)) -> 3 | AE12: =IF(AE10=AD10,1,IF(AE10>AD10,3,0)) -> 0 | AK12: =IF(AK10=AL10,1,IF(AK10>AL10,3,0)) -> 0 | AL12: =IF(AL10=AK10,1,IF(AL10>AK10,3,0)) -> 3
B14: Runde 2 | I14: Runde 2 | P14: Runde 2 | W14: Runde 2 | AD14: Runde 2 | AK14: Runde 2
B15: Tschechien | C15: Südafrika | I15: Schweiz | J15: Bosnien-Herz. | P15: Schottland | Q15: Marokko | W15: Türkei | X15: Paraguay | AD15: Ecuador | AE15: Curacao | AK15: Tunesien | AL15: Japan
B16: 1 | C16: 1 | I16: 2 | J16: 2 | P16: 1 | Q16: 3 | W16: 2 | X16: 2 | AD16: 4 | AE16: 1 | AK16: 1 | AL16: 3
B17: =IF(B16=C16,"Unentschieden",IF(B16>C16,B15,C15)) -> Unentschieden | I17: =IF(I16=J16,"Unentschieden",IF(I16>J16,I15,J15)) -> Unentschieden | P17: =IF(P16=Q16,"Unentschieden",IF(P16>Q16,P15,Q15)) -> Marokko | W17: =IF(W16=X16,"Unentschieden",IF(W16>X16,W15,X15)) -> Unentschieden | AD17: =IF(AD16=AE16,"Unentschieden",IF(AD16>AE16,AD15,AE15)) -> Ecuador | AK17: =IF(AK16=AL16,"Unentschieden",IF(AK16>AL16,AK15,AL15)) -> Japan
B18: =IF(B16=C16,1,IF(B16>C16,3,0)) -> 1 | C18: =IF(C16=B16,1,IF(C16>B16,3,0)) -> 1 | I18: =IF(I16=J16,1,IF(I16>J16,3,0)) -> 1 | J18: =IF(J16=I16,1,IF(J16>I16,3,0)) -> 1 | P18: =IF(P16=Q16,1,IF(P16>Q16,3,0)) -> 0 | Q18: =IF(Q16=P16,1,IF(Q16>P16,3,0)) -> 3 | W18: =IF(W16=X16,1,IF(W16>X16,3,0)) -> 1 | X18: =IF(X16=W16,1,IF(X16>W16,3,0)) -> 1 | AD18: =IF(AD16=AE16,1,IF(AD16>AE16,3,0)) -> 3 | AE18: =IF(AE16=AD16,1,IF(AE16>AD16,3,0)) -> 0 | AK18: =IF(AK16=AL16,1,IF(AK16>AL16,3,0)) -> 0 | AL18: =IF(AL16=AK16,1,IF(AL16>AK16,3,0)) -> 3
B20: Mexiko | C20: Südkorea | I20: Kanada | J20: Katar | P20: Brasilien | Q20: Haiti | W20: USA | X20: Australien | AD20: Deutschland | AE20: Elfenbeinküste | AK20: Niederlande | AL20: Schweden
B21: 2 | C21: 2 | I21: 2 | J21: 1 | P21: 4 | Q21: 0 | W21: 0 | X21: 0 | AD21: 1 | AE21: 3 | AK21: 3 | AL21: 0
B22: =IF(B21=C21,"Unentschieden",IF(B21>C21,B20,C20)) -> Unentschieden | I22: =IF(I21=J21,"Unentschieden",IF(I21>J21,I20,J20)) -> Kanada | P22: =IF(P21=Q21,"Unentschieden",IF(P21>Q21,P20,Q20)) -> Brasilien | W22: =IF(W21=X21,"Unentschieden",IF(W21>X21,W20,X20)) -> Unentschieden | AD22: =IF(AD21=AE21,"Unentschieden",IF(AD21>AE21,AD20,AE20)) -> Elfenbeinküste | AK22: =IF(AK21=AL21,"Unentschieden",IF(AK21>AL21,AK20,AL20)) -> Niederlande
B23: =IF(B21=C21,1,IF(B21>C21,3,0)) -> 1 | C23: =IF(C21=B21,1,IF(C21>B21,3,0)) -> 1 | I23: =IF(I21=J21,1,IF(I21>J21,3,0)) -> 3 | J23: =IF(J21=I21,1,IF(J21>I21,3,0)) -> 0 | P23: =IF(P21=Q21,1,IF(P21>Q21,3,0)) -> 3 | Q23: =IF(Q21=P21,1,IF(Q21>P21,3,0)) -> 0 | W23: =IF(W21=X21,1,IF(W21>X21,3,0)) -> 1 | X23: =IF(X21=W21,1,IF(X21>W21,3,0)) -> 1 | AD23: =IF(AD21=AE21,1,IF(AD21>AE21,3,0)) -> 0 | AE23: =IF(AE21=AD21,1,IF(AE21>AD21,3,0)) -> 3 | AK23: =IF(AK21=AL21,1,IF(AK21>AL21,3,0)) -> 3 | AL23: =IF(AL21=AK21,1,IF(AL21>AK21,3,0)) -> 0
B25: Runde 3 | I25: Runde 3 | P25: Runde 3 | W25: Runde 3 | AD25: Runde 3 | AK25: Runde 3
B26: Südafrika | C26: Südkorea | I26: Bosnien-Herz. | J26: Katar | P26: Marokko | Q26: Haiti | W26: Paraguay | X26: Australien | AD26: Curacao | AE26: Elfenbeinküste | AK26: Japan | AL26: Schweden
B27: 0 | C27: 3 | I27: 3 | J27: 0 | P27: 2 | Q27: 0 | W27: 2 | X27: 1 | AD27: 0 | AE27: 4 | AK27: 3 | AL27: 1
B28: =IF(B27=C27,"Unentschieden",IF(B27>C27,B26,C26)) -> Südkorea | I28: =IF(I27=J27,"Unentschieden",IF(I27>J27,I26,J26)) -> Bosnien-Herz. | P28: =IF(P27=Q27,"Unentschieden",IF(P27>Q27,P26,Q26)) -> Marokko | W28: =IF(W27=X27,"Unentschieden",IF(W27>X27,W26,X26)) -> Paraguay | AD28: =IF(AD27=AE27,"Unentschieden",IF(AD27>AE27,AD26,AE26)) -> Elfenbeinküste | AK28: =IF(AK27=AL27,"Unentschieden",IF(AK27>AL27,AK26,AL26)) -> Japan
B29: =IF(B27=C27,1,IF(B27>C27,3,0)) -> 0 | C29: =IF(C27=B27,1,IF(C27>B27,3,0)) -> 3 | I29: =IF(I27=J27,1,IF(I27>J27,3,0)) -> 3 | J29: =IF(J27=I27,1,IF(J27>I27,3,0)) -> 0 | P29: =IF(P27=Q27,1,IF(P27>Q27,3,0)) -> 3 | Q29: =IF(Q27=P27,1,IF(Q27>P27,3,0)) -> 0 | W29: =IF(W27=X27,1,IF(W27>X27,3,0)) -> 3 | X29: =IF(X27=W27,1,IF(X27>W27,3,0)) -> 0 | AD29: =IF(AD27=AE27,1,IF(AD27>AE27,3,0)) -> 0 | AE29: =IF(AE27=AD27,1,IF(AE27>AD27,3,0)) -> 3 | AK29: =IF(AK27=AL27,1,IF(AK27>AL27,3,0)) -> 3 | AL29: =IF(AL27=AK27,1,IF(AL27>AK27,3,0)) -> 0
B31: Tschechien | C31: Mexiko | I31: Schweiz | J31: Kanada | P31: Schottland | Q31: Brasilien | W31: Türkei | X31: USA | AD31: Ecuador | AE31: Deutschland | AK31: Tunesien | AL31: Niederlande
B32: 1 | C32: 2 | I32: 2 | J32: 1 | P32: 1 | Q32: 3 | W32: 3 | X32: 0 | AD32: 0 | AE32: 2 | AK32: 1 | AL32: 2
B33: =IF(B32=C32,"Unentschieden",IF(B32>C32,B31,C31)) -> Mexiko | I33: =IF(I32=J32,"Unentschieden",IF(I32>J32,I31,J31)) -> Schweiz | P33: =IF(P32=Q32,"Unentschieden",IF(P32>Q32,P31,Q31)) -> Brasilien | W33: =IF(W32=X32,"Unentschieden",IF(W32>X32,W31,X31)) -> Türkei | AD33: =IF(AD32=AE32,"Unentschieden",IF(AD32>AE32,AD31,AE31)) -> Deutschland | AK33: =IF(AK32=AL32,"Unentschieden",IF(AK32>AL32,AK31,AL31)) -> Niederlande
B34: =IF(B32=C32,1,IF(B32>C32,3,0)) -> 0 | C34: =IF(C32=B32,1,IF(C32>B32,3,0)) -> 3 | I34: =IF(I32=J32,1,IF(I32>J32,3,0)) -> 3 | J34: =IF(J32=I32,1,IF(J32>I32,3,0)) -> 0 | P34: =IF(P32=Q32,1,IF(P32>Q32,3,0)) -> 0 | Q34: =IF(Q32=P32,1,IF(Q32>P32,3,0)) -> 3 | W34: =IF(W32=X32,1,IF(W32>X32,3,0)) -> 3 | X34: =IF(X32=W32,1,IF(X32>W32,3,0)) -> 0 | AD34: =IF(AD32=AE32,1,IF(AD32>AE32,3,0)) -> 0 | AE34: =IF(AE32=AD32,1,IF(AE32>AD32,3,0)) -> 3 | AK34: =IF(AK32=AL32,1,IF(AK32>AL32,3,0)) -> 0 | AL34: =IF(AL32=AK32,1,IF(AL32>AK32,3,0)) -> 3
B36: Land | C36: Punkte | D36: T | E36: GT | F36: TD | I36: Land | J36: Punkte | K36: T | L36: GT | M36: TD | P36: Land | Q36: Punkte | R36: T | S36: GT | T36: TD | W36: Land | X36: Punkte | Y36: T | Z36: GT | AA36: TD | AD36: Land | AE36: Punkte | AF36: T | AG36: GT | AH36: TD | AK36: Land | AL36: Punkte | AM36: T | AN36: GT | AO36: TD
B37: Mexiko | C37: =B7+B23+C34 -> 7 | D37: =B5+B21+C32 -> 6 | E37: =C5+C21+B32 -> 3 | F37: =D37-E37 -> 3 | I37: Kanada | J37: =I7+I23+J34 -> 3 | K37: =I5+I21+J32 -> 4 | L37: =J5+J21+I32 -> 6 | M37: =K37-L37 -> -2 | P37: Brasilien | Q37: =P7+P23+Q34 -> 9 | R37: =P5+P21+Q32 -> 9 | S37: =Q5+Q21+P32 -> 1 | T37: =R37-S37 -> 8 | W37: USA | X37: =W7+W23+X34 -> 1 | Y37: =W5+W21+X32 -> 0 | Z37: =X5+X21+W32 -> 5 | AA37: =Y37-Z37 -> -5 | AD37: Deutschland | AE37: =AD7+AD23+AE34 -> 6 | AF37: =AD5+AD21+AE32 -> 7 | AG37: =AE5+AE21+AD32 -> 3 | AH37: =AF37-AG37 -> 4 | AK37: Niederlande | AL37: =AK7+AK23+AL34 -> 6 | AM37: =AK5+AK21+AL32 -> 6 | AN37: =AL5+AL21+AK32 -> 3 | AO37: =AM37-AN37 -> 3
B38: Südafrika | C38: =C7+C18+B29 -> 1 | D38: =C5+C16+B27 -> 1 | E38: =B5+B16+C27 -> 6 | F38: =D38-E38 -> -5 | I38: Bosnien-Herz. | J38: =J7+J18+I29 -> 7 | K38: =J5+J16+I27 -> 8 | L38: =I5+I16+J27 -> 3 | M38: =K38-L38 -> 5 | P38: Marokko | Q38: =Q7+Q18+P29 -> 6 | R38: =Q5+Q16+P27 -> 5 | S38: =P5+P16+Q27 -> 3 | T38: =R38-S38 -> 2 | W38: Paraguay | X38: =X7+X18+W29 -> 7 | Y38: =X5+X16+W27 -> 6 | Z38: =W5+W16+X27 -> 3 | AA38: =Y38-Z38 -> 3 | AD38: Curacao | AE38: =AE7+AE18+AD29 -> 0 | AF38: =AE5+AE16+AD27 -> 1 | AG38: =AD5+AD16+AE27 -> 12 | AH38: =AF38-AG38 -> -11 | AK38: Japan | AL38: =AL7+AL18+AK29 -> 9 | AM38: =AL5+AL16+AK27 -> 8 | AN38: =AK5+AK16+AL27 -> 3 | AO38: =AM38-AN38 -> 5
B39: Südkorea | C39: =B12+C23+C29 -> 7 | D39: =B10+C21+C27 -> 7 | E39: =C10+B21+B27 -> 3 | F39: =D39-E39 -> 4 | I39: Katar | J39: =I12+J23+J29 -> 0 | K39: =I10+J21+J27 -> 1 | L39: =J10+I21+I27 -> 8 | M39: =K39-L39 -> -7 | P39: Haiti | Q39: =P12+Q23+Q29 -> 0 | R39: =P10+Q21+Q27 -> 0 | S39: =Q10+P21+P27 -> 7 | T39: =R39-S39 -> -7 | W39: Australien | X39: =W12+X23+X29 -> 1 | Y39: =W10+X21+X27 -> 2 | Z39: =X10+W21+W27 -> 5 | AA39: =Y39-Z39 -> -3 | AD39: Elfenbeinküste | AE39: =AD12+AE23+AE29 -> 9 | AF39: =AD10+AE21+AE27 -> 10 | AG39: =AE10+AD21+AD27 -> 3 | AH39: =AF39-AG39 -> 7 | AK39: Schweden | AL39: =AK12+AL23+AL29 -> 0 | AM39: =AK10+AL21+AL27 -> 1 | AN39: =AL10+AK21+AK27 -> 8 | AO39: =AM39-AN39 -> -7
B40: Tschechien | C40: =C12+B18+B34 -> 1 | D40: =C10+B16+B32 -> 3 | E40: =B10+C16+C32 -> 5 | F40: =D40-E40 -> -2 | I40: Schweiz | J40: =J12+I18+I34 -> 7 | K40: =J10+I16+I32 -> 7 | L40: =I10+J16+J32 -> 3 | M40: =K40-L40 -> 4 | P40: Schottland | Q40: =Q12+P18+P34 -> 3 | R40: =Q10+P16+P32 -> 3 | S40: =P10+Q16+Q32 -> 6 | T40: =R40-S40 -> -3 | W40: Türkei | X40: =X12+W18+W34 -> 7 | Y40: =X10+W16+W32 -> 8 | Z40: =W10+X16+X32 -> 3 | AA40: =Y40-Z40 -> 5 | AD40: Ecuador | AE40: =AE12+AD18+AD34 -> 3 | AF40: =AE10+AD16+AD32 -> 6 | AG40: =AD10+AE16+AE32 -> 6 | AH40: =AF40-AG40 -> 0 | AK40: Tunesien | AL40: =AL12+AK18+AK34 -> 3 | AM40: =AL10+AK16+AK32 -> 4 | AN40: =AK10+AL16+AL32 -> 5 | AO40: =AM40-AN40 -> -1
B42: Rangliste: | I42: Rangliste: | P42: Rangliste: | W42: Rangliste: | AD42: Rangliste: | AK42: Rangliste:
A43: 1 | B43: {=_xlfn.SORTBY(B37:B40,C37:C40,-1,F37:F40,-1,D37:D40,-1)} -> Südkorea | C43: {=_xlfn.SORTBY(C37:C40,C37:C40,-1,F37:F40,-1,D37:D40,-1)} -> 7 | D43: {=_xlfn.SORTBY(D37:D40,C37:C40,-1,F37:F40,-1,D37:D40,-1)} -> 7 | E43: {=_xlfn.SORTBY(E37:E40,C37:C40,-1,F37:F40,-1,D37:D40,-1)} -> 3 | F43: {=_xlfn.SORTBY(F37:F40,C37:C40,-1,F37:F40,-1,D37:D40,-1)} -> 4 | H43: 1 | I43: {=_xlfn.SORTBY(I37:I40,J37:J40,-1,M37:M40,-1,K37:K40,-1)} -> Bosnien-Herz. | J43: {=_xlfn.SORTBY(J37:J40,J37:J40,-1,M37:M40,-1,K37:K40,-1)} -> 7 | K43: {=_xlfn.SORTBY(K37:K40,J37:J40,-1,M37:M40,-1,K37:K40,-1)} -> 8 | L43: {=_xlfn.SORTBY(L37:L40,J37:J40,-1,M37:M40,-1,K37:K40,-1)} -> 3 | M43: {=_xlfn.SORTBY(M37:M40,J37:J40,-1,M37:M40,-1,K37:K40,-1)} -> 5 | O43: 1 | P43: {=_xlfn.SORTBY(P37:P40,Q37:Q40,-1,T37:T40,-1,R37:R40,-1)} -> Brasilien | Q43: {=_xlfn.SORTBY(Q37:Q40,Q37:Q40,-1,T37:T40,-1,R37:R40,-1)} -> 9 | R43: {=_xlfn.SORTBY(R37:R40,Q37:Q40,-1,T37:T40,-1,R37:R40,-1)} -> 9 | S43: {=_xlfn.SORTBY(S37:S40,Q37:Q40,-1,T37:T40,-1,R37:R40,-1)} -> 1 | T43: {=_xlfn.SORTBY(T37:T40,Q37:Q40,-1,T37:T40,-1,R37:R40,-1)} -> 8 | V43: 1 | W43: {=_xlfn.SORTBY(W37:W40,X37:X40,-1,AA37:AA40,-1,Y37:Y40,-1)} -> Türkei | X43: {=_xlfn.SORTBY(X37:X40,X37:X40,-1,AA37:AA40,-1,Y37:Y40,-1)} -> 7 | Y43: {=_xlfn.SORTBY(Y37:Y40,X37:X40,-1,AA37:AA40,-1,Y37:Y40,-1)} -> 8 | Z43: {=_xlfn.SORTBY(Z37:Z40,X37:X40,-1,AA37:AA40,-1,Y37:Y40,-1)} -> 3 | AA43: {=_xlfn.SORTBY(AA37:AA40,X37:X40,-1,AA37:AA40,-1,Y37:Y40,-1)} -> 5 | AC43: 1 | AD43: {=_xlfn.SORTBY(AD37:AD40,AE37:AE40,-1,AH37:AH40,-1,AF37:AF40,-1)} -> Elfenbeinküste | AE43: {=_xlfn.SORTBY(AE37:AE40,AE37:AE40,-1,AH37:AH40,-1,AF37:AF40,-1)} -> 9 | AF43: {=_xlfn.SORTBY(AF37:AF40,AE37:AE40,-1,AH37:AH40,-1,AF37:AF40,-1)} -> 10 | AG43: {=_xlfn.SORTBY(AG37:AG40,AE37:AE40,-1,AH37:AH40,-1,AF37:AF40,-1)} -> 3 | AH43: {=_xlfn.SORTBY(AH37:AH40,AE37:AE40,-1,AH37:AH40,-1,AF37:AF40,-1)} -> 7 | AJ43: 1 | AK43: {=_xlfn.SORTBY(AK37:AK40,AL37:AL40,-1,AO37:AO40,-1,AM37:AM40,-1)} -> Japan | AL43: {=_xlfn.SORTBY(AL37:AL40,AL37:AL40,-1,AO37:AO40,-1,AM37:AM40,-1)} -> 9 | AM43: {=_xlfn.SORTBY(AM37:AM40,AL37:AL40,-1,AO37:AO40,-1,AM37:AM40,-1)} -> 8 | AN43: {=_xlfn.SORTBY(AN37:AN40,AL37:AL40,-1,AO37:AO40,-1,AM37:AM40,-1)} -> 3 | AO43: {=_xlfn.SORTBY(AO37:AO40,AL37:AL40,-1,AO37:AO40,-1,AM37:AM40,-1)} -> 5
A44: 2 | B44: Mexiko | C44: 7 | D44: 6 | E44: 3 | F44: 3 | H44: 2 | I44: Schweiz | J44: 7 | K44: 7 | L44: 3 | M44: 4 | O44: 2 | P44: Marokko | Q44: 6 | R44: 5 | S44: 3 | T44: 2 | V44: 2 | W44: Paraguay | X44: 7 | Y44: 6 | Z44: 3 | AA44: 3 | AC44: 2 | AD44: Deutschland | AE44: 6 | AF44: 7 | AG44: 3 | AH44: 4 | AJ44: 2 | AK44: Niederlande | AL44: 6 | AM44: 6 | AN44: 3 | AO44: 3
A45: 3 | B45: Tschechien | C45: 1 | D45: 3 | E45: 5 | F45: -2 | H45: 3 | I45: Kanada | J45: 3 | K45: 4 | L45: 6 | M45: -2 | O45: 3 | P45: Schottland | Q45: 3 | R45: 3 | S45: 6 | T45: -3 | V45: 3 | W45: Australien | X45: 1 | Y45: 2 | Z45: 5 | AA45: -3 | AC45: 3 | AD45: Ecuador | AE45: 3 | AF45: 6 | AG45: 6 | AH45: 0 | AJ45: 3 | AK45: Tunesien | AL45: 3 | AM45: 4 | AN45: 5 | AO45: -1
A46: 4 | B46: Südafrika | C46: 1 | D46: 1 | E46: 6 | F46: -5 | H46: 4 | I46: Katar | J46: 0 | K46: 1 | L46: 8 | M46: -7 | O46: 4 | P46: Haiti | Q46: 0 | R46: 0 | S46: 7 | T46: -7 | V46: 4 | W46: USA | X46: 1 | Y46: 0 | Z46: 5 | AA46: -5 | AC46: 4 | AD46: Curacao | AE46: 0 | AF46: 1 | AG46: 12 | AH46: -11 | AJ46: 4 | AK46: Schweden | AL46: 0 | AM46: 1 | AN46: 8 | AO46: -7
A48: Gruppe G | H48: Gruppe H | O48: Gruppe I | V48: Gruppe J | AC48: Gruppe K | AJ48: Gruppe L
B50: Runde 1 | I50: Runde 1 | P50: Runde 1 | W50: Runde 1 | AD50: Runde 1 | AK50: Runde 1
...

Sheet Nici
B1: Gruppe A | H1: Gruppe B | O1: Gruppe C | V1: Gruppe D | AC1: Gruppe E | AJ1: Gruppe F
B3: Runde 1 | I3: Runde 1 | P3: Runde 1 | W3: Runde 1 | AD3: Runde 1 | AK3: Runde 1
B4: Mexiko | C4: Südafrika | I4: Kanada | J4: Bosnien-Herz. | P4: Brasilien | Q4: Marokko | W4: USA | X4: Paraguay | AD4: Deutschland | AE4: Curacao | AK4: Niederlande | AL4: Japan
B5: 1 | C5: 0 | I5: 1 | J5: 0 | P5: 1 | Q5: 1 | W5: 1 | X5: 0 | AD5: 3 | AE5: 0 | AK5: 1 | AL5: 1
B6: =IF(B5=C5,"Unentschieden",IF(B5>C5,B4,C4)) -> Mexiko | I6: =IF(I5=J5,"Unentschieden",IF(I5>J5,I4,J4)) -> Kanada | P6: =IF(P5=Q5,"Unentschieden",IF(P5>Q5,P4,Q4)) -> Unentschieden | W6: =IF(W5=X5,"Unentschieden",IF(W5>X5,W4,X4)) -> USA | AD6: =IF(AD5=AE5,"Unentschieden",IF(AD5>AE5,AD4,AE4)) -> Deutschland | AK6: =IF(AK5=AL5,"Unentschieden",IF(AK5>AL5,AK4,AL4)) -> Unentschieden
B7: =IF(B5=C5,1,IF(B5>C5,3,0)) -> 3 | C7: =IF(C5=B5,1,IF(C5>B5,3,0)) -> 0 | I7: =IF(I5=J5,1,IF(I5>J5,3,0)) -> 3 | J7: =IF(J5=I5,1,IF(J5>I5,3,0)) -> 0 | P7: =IF(P5=Q5,1,IF(P5>Q5,3,0)) -> 1 | Q7: =IF(Q5=P5,1,IF(Q5>P5,3,0)) -> 1 | W7: =IF(W5=X5,1,IF(W5>X5,3,0)) -> 3 | X7: =IF(X5=W5,1,IF(X5>W5,3,0)) -> 0 | AD7: =IF(AD5=AE5,1,IF(AD5>AE5,3,0)) -> 3 | AE7: =IF(AE5=AD5,1,IF(AE5>AD5,3,0)) -> 0 | AK7: =IF(AK5=AL5,1,IF(AK5>AL5,3,0)) -> 1 | AL7: =IF(AL5=AK5,1,IF(AL5>AK5,3,0)) -> 1
B9: Südkorea | C9: Tschechien | I9: Katar | J9: Schweiz | P9: Haiti | Q9: Schottland | W9: Australien | X9: Türkei | AD9: Elfenbeinküste | AE9: Ecuador | AK9: Schweden | AL9: Tunesien
B10: 1 | C10: 1 | I10: 0 | J10: 2 | P10: 1 | Q10: 2 | W10: 1 | X10: 1 | AD10: 0 | AE10: 1 | AK10: 1 | AL10: 1
B11: =IF(B10=C10,"Unentschieden",IF(B10>C10,B9,C9)) -> Unentschieden | I11: =IF(I10=J10,"Unentschieden",IF(I10>J10,I9,J9)) -> Schweiz | P11: =IF(P10=Q10,"Unentschieden",IF(P10>Q10,P9,Q9)) -> Schottland | W11: =IF(W10=X10,"Unentschieden",IF(W10>X10,W9,X9)) -> Unentschieden | AD11: =IF(AD10=AE10,"Unentschieden",IF(AD10>AE10,AD9,AE9)) -> Ecuador | AK11: =IF(AK10=AL10,"Unentschieden",IF(AK10>AL10,AK9,AL9)) -> Unentschieden
B12: =IF(B10=C10,1,IF(B10>C10,3,0)) -> 1 | C12: =IF(C10=B10,1,IF(C10>B10,3,0)) -> 1 | I12: =IF(I10=J10,1,IF(I10>J10,3,0)) -> 0 | J12: =IF(J10=I10,1,IF(J10>I10,3,0)) -> 3 | P12: =IF(P10=Q10,1,IF(P10>Q10,3,0)) -> 0 | Q12: =IF(Q10=P10,1,IF(Q10>P10,3,0)) -> 3 | W12: =IF(W10=X10,1,IF(W10>X10,3,0)) -> 1 | X12: =IF(X10=W10,1,IF(X10>W10,3,0)) -> 1 | AD12: =IF(AD10=AE10,1,IF(AD10>AE10,3,0)) -> 0 | AE12: =IF(AE10=AD10,1,IF(AE10>AD10,3,0)) -> 3 | AK12: =IF(AK10=AL10,1,IF(AK10>AL10,3,0)) -> 1 | AL12: =IF(AL10=AK10,1,IF(AL10>AK10,3,0)) -> 1
B14: Runde 2 | I14: Runde 2 | P14: Runde 2 | W14: Runde 2 | AD14: Runde 2 | AK14: Runde 2
B15: Tschechien | C15: Südafrika | I15: Schweiz | J15: Bosnien-Herz. | P15: Schottland | Q15: Marokko | W15: Türkei | X15: Paraguay | AD15: Ecuador | AE15: Curacao | AK15: Tunesien | AL15: Japan
B16: 1 | C16: 0 | I16: 2 | J16: 0 | P16: 1 | Q16: 1 | W16: 1 | X16: 0 | AD16: 2 | AE16: 0 | AK16: 0 | AL16: 2
B17: =IF(B16=C16,"Unentschieden",IF(B16>C16,B15,C15)) -> Tschechien | I17: =IF(I16=J16,"Unentschieden",IF(I16>J16,I15,J15)) -> Schweiz | P17: =IF(P16=Q16,"Unentschieden",IF(P16>Q16,P15,Q15)) -> Unentschieden | W17: =IF(W16=X16,"Unentschieden",IF(W16>X16,W15,X15)) -> Türkei | AD17: =IF(AD16=AE16,"Unentschieden",IF(AD16>AE16,AD15,AE15)) -> Ecuador | AK17: =IF(AK16=AL16,"Unentschieden",IF(AK16>AL16,AK15,AL15)) -> Japan
B18: =IF(B16=C16,1,IF(B16>C16,3,0)) -> 3 | C18: =IF(C16=B16,1,IF(C16>B16,3,0)) -> 0 | I18: =IF(I16=J16,1,IF(I16>J16,3,0)) -> 3 | J18: =IF(J16=I16,1,IF(J16>I16,3,0)) -> 0 | P18: =IF(P16=Q16,1,IF(P16>Q16,3,0)) -> 1 | Q18: =IF(Q16=P16,1,IF(Q16>P16,3,0)) -> 1 | W18: =IF(W16=X16,1,IF(W16>X16,3,0)) -> 3 | X18: =IF(X16=W16,1,IF(X16>W16,3,0)) -> 0 | AD18: =IF(AD16=AE16,1,IF(AD16>AE16,3,0)) -> 3 | AE18: =IF(AE16=AD16,1,IF(AE16>AD16,3,0)) -> 0 | AK18: =IF(AK16=AL16,1,IF(AK16>AL16,3,0)) -> 0 | AL18: =IF(AL16=AK16,1,IF(AL16>AK16,3,0)) -> 3
B20: Mexiko | C20: Südkorea | I20: Kanada | J20: Katar | P20: Brasilien | Q20: Haiti | W20: USA | X20: Australien | AD20: Deutschland | AE20: Elfenbeinküste | AK20: Niederlande | AL20: Schweden
B21: 1 | C21: 1 | I21: 1 | J21: 0 | P21: 3 | Q21: 0 | W21: 1 | X21: 1 | AD21: 2 | AE21: 1 | AK21: 2 | AL21: 1
B22: =IF(B21=C21,"Unentschieden",IF(B21>C21,B20,C20)) -> Unentschieden | I22: =IF(I21=J21,"Unentschieden",IF(I21>J21,I20,J20)) -> Kanada | P22: =IF(P21=Q21,"Unentschieden",IF(P21>Q21,P20,Q20)) -> Brasilien | W22: =IF(W21=X21,"Unentschieden",IF(W21>X21,W20,X20)) -> Unentschieden | AD22: =IF(AD21=AE21,"Unentschieden",IF(AD21>AE21,AD20,AE20)) -> Deutschland | AK22: =IF(AK21=AL21,"Unentschieden",IF(AK21>AL21,AK20,AL20)) -> Niederlande
B23: =IF(B21=C21,1,IF(B21>C21,3,0)) -> 1 | C23: =IF(C21=B21,1,IF(C21>B21,3,0)) -> 1 | I23: =IF(I21=J21,1,IF(I21>J21,3,0)) -> 3 | J23: =IF(J21=I21,1,IF(J21>I21,3,0)) -> 0 | P23: =IF(P21=Q21,1,IF(P21>Q21,3,0)) -> 3 | Q23: =IF(Q21=P21,1,IF(Q21>P21,3,0)) -> 0 | W23: =IF(W21=X21,1,IF(W21>X21,3,0)) -> 1 | X23: =IF(X21=W21,1,IF(X21>W21,3,0)) -> 1 | AD23: =IF(AD21=AE21,1,IF(AD21>AE21,3,0)) -> 3 | AE23: =IF(AE21=AD21,1,IF(AE21>AD21,3,0)) -> 0 | AK23: =IF(AK21=AL21,1,IF(AK21>AL21,3,0)) -> 3 | AL23: =IF(AL21=AK21,1,IF(AL21>AK21,3,0)) -> 0
B25: Runde 3 | I25: Runde 3 | P25: Runde 3 | W25: Runde 3 | AD25: Runde 3 | AK25: Runde 3
B26: Südafrika | C26: Südkorea | I26: Bosnien-Herz. | J26: Katar | P26: Marokko | Q26: Haiti | W26: Paraguay | X26: Australien | AD26: Curacao | AE26: Elfenbeinküste | AK26: Japan | AL26: Schweden
B27: 0 | C27: 1 | I27: 1 | J27: 1 | P27: 2 | Q27: 0 | W27: 1 | X27: 1 | AD27: 0 | AE27: 1 | AK27: 2 | AL27: 1
B28: =IF(B27=C27,"Unentschieden",IF(B27>C27,B26,C26)) -> Südkorea | I28: =IF(I27=J27,"Unentschieden",IF(I27>J27,I26,J26)) -> Unentschieden | P28: =IF(P27=Q27,"Unentschieden",IF(P27>Q27,P26,Q26)) -> Marokko | W28: =IF(W27=X27,"Unentschieden",IF(W27>X27,W26,X26)) -> Unentschieden | AD28: =IF(AD27=AE27,"Unentschieden",IF(AD27>AE27,AD26,AE26)) -> Elfenbeinküste | AK28: =IF(AK27=AL27,"Unentschieden",IF(AK27>AL27,AK26,AL26)) -> Japan
B29: =IF(B27=C27,1,IF(B27>C27,3,0)) -> 0 | C29: =IF(C27=B27,1,IF(C27>B27,3,0)) -> 3 | I29: =IF(I27=J27,1,IF(I27>J27,3,0)) -> 1 | J29: =IF(J27=I27,1,IF(J27>I27,3,0)) -> 1 | P29: =IF(P27=Q27,1,IF(P27>Q27,3,0)) -> 3 | Q29: =IF(Q27=P27,1,IF(Q27>P27,3,0)) -> 0 | W29: =IF(W27=X27,1,IF(W27>X27,3,0)) -> 1 | X29: =IF(X27=W27,1,IF(X27>W27,3,0)) -> 1 | AD29: =IF(AD27=AE27,1,IF(AD27>AE27,3,0)) -> 0 | AE29: =IF(AE27=AD27,1,IF(AE27>AD27,3,0)) -> 3 | AK29: =IF(AK27=AL27,1,IF(AK27>AL27,3,0)) -> 3 | AL29: =IF(AL27=AK27,1,IF(AL27>AK27,3,0)) -> 0
B31: Tschechien | C31: Mexiko | I31: Schweiz | J31: Kanada | P31: Schottland | Q31: Brasilien | W31: Türkei | X31: USA | AD31: Ecuador | AE31: Deutschland | AK31: Tunesien | AL31: Niederlande
B32: 1 | C32: 1 | I32: 1 | J32: 1 | P32: 0 | Q32: 2 | W32: 1 | X32: 1 | AD32: 0 | AE32: 1 | AK32: 0 | AL32: 2
B33: =IF(B32=C32,"Unentschieden",IF(B32>C32,B31,C31)) -> Unentschieden | I33: =IF(I32=J32,"Unentschieden",IF(I32>J32,I31,J31)) -> Unentschieden | P33: =IF(P32=Q32,"Unentschieden",IF(P32>Q32,P31,Q31)) -> Brasilien | W33: =IF(W32=X32,"Unentschieden",IF(W32>X32,W31,X31)) -> Unentschieden | AD33: =IF(AD32=AE32,"Unentschieden",IF(AD32>AE32,AD31,AE31)) -> Deutschland | AK33: =IF(AK32=AL32,"Unentschieden",IF(AK32>AL32,AK31,AL31)) -> Niederlande
B34: =IF(B32=C32,1,IF(B32>C32,3,0)) -> 1 | C34: =IF(C32=B32,1,IF(C32>B32,3,0)) -> 1 | I34: =IF(I32=J32,1,IF(I32>J32,3,0)) -> 1 | J34: =IF(J32=I32,1,IF(J32>I32,3,0)) -> 1 | P34: =IF(P32=Q32,1,IF(P32>Q32,3,0)) -> 0 | Q34: =IF(Q32=P32,1,IF(Q32>P32,3,0)) -> 3 | W34: =IF(W32=X32,1,IF(W32>X32,3,0)) -> 1 | X34: =IF(X32=W32,1,IF(X32>W32,3,0)) -> 1 | AD34: =IF(AD32=AE32,1,IF(AD32>AE32,3,0)) -> 0 | AE34: =IF(AE32=AD32,1,IF(AE32>AD32,3,0)) -> 3 | AK34: =IF(AK32=AL32,1,IF(AK32>AL32,3,0)) -> 0 | AL34: =IF(AL32=AK32,1,IF(AL32>AK32,3,0)) -> 3
B36: Land | C36: Punkte | D36: T | E36: GT | F36: TD | I36: Land | J36: Punkte | K36: T | L36: GT | M36: TD | P36: Land | Q36: Punkte | R36: T | S36: GT | T36: TD | W36: Land | X36: Punkte | Y36: T | Z36: GT | AA36: TD | AD36: Land | AE36: Punkte | AF36: T | AG36: GT | AH36: TD | AK36: Land | AL36: Punkte | AM36: T | AN36: GT | AO36: TD
